Workbook
Name animales: #REF!

Sheet Parametros
A1: Apellido y Nombre | B1: Cargar Apellido
A2: Legajo | B2: ingrese legajo
A8: Horarios | B8: Estacion Año | D8: Diurnos | F8: Nocturnos
B9: Desde | C9: hasta | D9: Desde | E9: Hasta | F9: Desde | G9: Hasta
A10: Verano | B10: 1221 | C10: 320 | D10: 0.375 | E10: 0.95833333 | F10: 0.95902778 | G10: 0.37430556
A11: otoño | B11: 321 | C11: 620 | D11: 0.41666667 | E11: 0.875 | F11: 0.87569444 | G11: 0.41597222
A12: Invierno | B12: 621 | C12: 920 | D12: 0.41666667 | E12: 0.89583333 | F12: 0.89652778 | G12: 0.41597222
A13: Primavera | B13: 921 | C13: 1220 | D13: 0.35416667 | E13: 0.9375 | F13: 0.93819444 | G13: 0.35347222
A16: Aeropuertos | B16: CODIGO | D16: Autor Planilla | E16: Contacto | F16: Puesto
A17: El Palomar | B17: EPA | D17: Ayelen Bertora | E17: ayelenbertora@flybondi.com | F17: TCP
A18: Bahía Blanca | B18: BHI
A19: Bariloche | B19: BRC | D19: Aviones
A20: Corrientes | B20: CNQ | D20: Nombre | E20: Codigo
A21: Córdoba | B21: COR | D21: avion 1 | E21: LV-HKN
A22: Puerto Iguazú | B22: IGR | D22: avion 2 | E22: LV-KAH
A23: Perico | B23: JUJ | D23: avion 3 | E23: LV-KAY
A24: Mendoza | B24: MDZ | D24: avion 4 | E24: LV-KCD
A25: Neuquén | B25: NQN | D25: avion 5 | E25: LV-KCE
A26: Posadas | B26: PSS | D26: avion 6 | E26: LV-KDQ
A27: Trelew | B27: REL | D27: avion 7 | E27: LV-KDR
A28: Resistencia | B28: RES | D28: avion 8 | E28: LV-KEH
A29: Rosario | B29: ROS | D29: avion 9 | E29: LV-KDR
A30: Santiago del Estero | B30: SDE | D30: avion 10 | E30: LV-KEG
A31: Salta | B31: SLA | D31: avion 11 | E31: LV-KEH
... A60: El Calafate - Santa Cruz | B60: FTE | D60: avion 40 | E60: AGREGAR MATRICULA
A61: Gobernador Gregores - Santa Cruz | B61: GGS
A62: Gualeguaychú - Entre Ríos | B62: GHU
A63: General Roca - Río Negro | B63: GNR
A64: General Pico - La Pampa | B64: GPO
A65: Chos Malal - Neuquén | B65: HOS
A66: Ingeniero Jacobacci - Río Negro | B66: IGB
A67: La Rioja - La Rioja | B67: IRJ
A68: Junín - Buenos Aires | B68: JNI
A69: José de San Martín - Chubut | B69: JSM
A70: La Cumbre - Córdoba | B70: LCM
A71: Loncopué - Neuquén | B71: LCP
A72: Malargüe - Mendoza | B72: LGS
... A141: Nuevo aeropuerto | B141: CODIGO NUEVO

Sheet TOTALES MENSUALES
A2: TOTALES MENSUALES
A4: AÑO | B4: MES | C4: TOTAL TV | D4: TOTAL TSV | E4: TV ADIC 45 | F4: Fecha
A5: =YEAR(F5) -> 2024 | B5: =MONTH(F5) -> 1 | C5: =SUMIFS('TOTALES DIARIOS'!$G$4:$G$508,'TOTALES DIARIOS'!$L$4:$L$508,'TOTALES MENSUALES'!B5,'TOTALES DIARIOS'!$K$4:$K$508,'TOTALES MENSUALES'!A5) -> 1.5 | D5: =SUMIFS('TOTALES DIARIOS'!$H$4:$H$508,'TOTALES DIARIOS'!$L$4:$L$508,'TOTALES MENSUALES'!B5,'TOTALES DIARIOS'!$K$4:$K$508,'TOTALES MENSUALES'!A5) -> 2.5 | E5: =IF(C5>45,C5-45,0) -> 0 | F5: =DATEVALUE(CONCATENATE(1,"/",MONTH('TOTALES DIARIOS'!A4),"/",YEAR('TOTALES DIARIOS'!A4))) -> 45292
A6: =YEAR(F6) -> 2024 | B6: =MONTH(F6) -> 2 | C6: =SUMIFS('TOTALES DIARIOS'!$G$4:$G$508,'TOTALES DIARIOS'!$L$4:$L$508,'TOTALES MENSUALES'!B6,'TOTALES DIARIOS'!$K$4:$K$508,'TOTALES MENSUALES'!A6) -> 0 | D6: =SUMIFS('TOTALES DIARIOS'!$H$4:$H$508,'TOTALES DIARIOS'!$L$4:$L$508,'TOTALES MENSUALES'!B6,'TOTALES DIARIOS'!$K$4:$K$508,'TOTALES MENSUALES'!A6) -> 0 | E6: =IF(C6>45,C6-45,0) -> 0 | F6: =DATE(A5,B5,32) -> 45323
A7: =YEAR(F7) -> 2024 | B7: =MONTH(F7) -> 3 | C7: =SUMIFS('TOTALES DIARIOS'!$G$4:$G$508,'TOTALES DIARIOS'!$L$4:$L$508,'TOTALES MENSUALES'!B7,'TOTALES DIARIOS'!$K$4:$K$508,'TOTALES MENSUALES'!A7) -> 0 | D7: =SUMIFS('TOTALES DIARIOS'!$H$4:$H$508,'TOTALES DIARIOS'!$L$4:$L$508,'TOTALES MENSUALES'!B7,'TOTALES DIARIOS'!$K$4:$K$508,'TOTALES MENSUALES'!A7) -> 0 | E7: =IF(C7>45,C7-45,0) -> 0 | F7: =F6+31 -> 45354
A8: =YEAR(F8) -> 2024 | B8: =MONTH(F8) -> 4 | C8: =SUMIFS('TOTALES DIARIOS'!$G$4:$G$508,'TOTALES DIARIOS'!$L$4:$L$508,'TOTALES MENSUALES'!B8,'TOTALES DIARIOS'!$K$4:$K$508,'TOTALES MENSUALES'!A8) -> 0 | D8: =SUMIFS('TOTALES DIARIOS'!$H$4:$H$508,'TOTALES DIARIOS'!$L$4:$L$508,'TOTALES MENSUALES'!B8,'TOTALES DIARIOS'!$K$4:$K$508,'TOTALES MENSUALES'!A8) -> 0 | E8: =IF(C8>45,C8-45,0) -> 0 | F8: =F7+31 -> 45385
A9: =YEAR(F9) -> 2024 | B9: =MONTH(F9) -> 5 | C9: =SUMIFS('TOTALES DIARIOS'!$G$4:$G$508,'TOTALES DIARIOS'!$L$4:$L$508,'TOTALES MENSUALES'!B9,'TOTALES DIARIOS'!$K$4:$K$508,'TOTALES MENSUALES'!A9) -> 0 | D9: =SUMIFS('TOTALES DIARIOS'!$H$4:$H$508,'TOTALES DIARIOS'!$L$4:$L$508,'TOTALES MENSUALES'!B9,'TOTALES DIARIOS'!$K$4:$K$508,'TOTALES MENSUALES'!A9) -> 0 | E9: =IF(C9>45,C9-45,0) -> 0 | F9: =F8+31 -> 45416
A10: =YEAR(F10) -> 2024 | B10: =MONTH(F10) -> 6 | C10: =SUMIFS('TOTALES DIARIOS'!$G$4:$G$508,'TOTALES DIARIOS'!$L$4:$L$508,'TOTALES MENSUALES'!B10,'TOTALES DIARIOS'!$K$4:$K$508,'TOTALES MENSUALES'!A10) -> 0 | D10: =SUMIFS('TOTALES DIARIOS'!$H$4:$H$508,'TOTALES DIARIOS'!$L$4:$L$508,'TOTALES MENSUALES'!B10,'TOTALES DIARIOS'!$K$4:$K$508,'TOTALES MENSUALES'!A10) -> 0 | E10: =IF(C10>45,C10-45,0) -> 0 | F10: =F9+31 -> 45447
A11: =YEAR(F11) -> 2024 | B11: =MONTH(F11) -> 7 | C11: =SUMIFS('TOTALES DIARIOS'!$G$4:$G$508,'TOTALES DIARIOS'!$L$4:$L$508,'TOTALES MENSUALES'!B11,'TOTALES DIARIOS'!$K$4:$K$508,'TOTALES MENSUALES'!A11) -> 0 | D11: =SUMIFS('TOTALES DIARIOS'!$H$4:$H$508,'TOTALES DIARIOS'!$L$4:$L$508,'TOTALES MENSUALES'!B11,'TOTALES DIARIOS'!$K$4:$K$508,'TOTALES MENSUALES'!A11) -> 0 | E11: =IF(C11>45,C11-45,0) -> 0 | F11: =F10+31 -> 45478
A12: =YEAR(F12) -> 2024 | B12: =MONTH(F12) -> 8 | C12: =SUMIFS('TOTALES DIARIOS'!$G$4:$G$508,'TOTALES DIARIOS'!$L$4:$L$508,'TOTALES MENSUALES'!B12,'TOTALES DIARIOS'!$K$4:$K$508,'TOTALES MENSUALES'!A12) -> 0 | D12: =SUMIFS('TOTALES DIARIOS'!$H$4:$H$508,'TOTALES DIARIOS'!$L$4:$L$508,'TOTALES MENSUALES'!B12,'TOTALES DIARIOS'!$K$4:$K$508,'TOTALES MENSUALES'!A12) -> 0 | E12: =IF(C12>45,C12-45,0) -> 0 | F12: =F11+31 -> 45509
A13: =YEAR(F13) -> 2024 | B13: =MONTH(F13) -> 9 | C13: =SUMIFS('TOTALES DIARIOS'!$G$4:$G$508,'TOTALES DIARIOS'!$L$4:$L$508,'TOTALES MENSUALES'!B13,'TOTALES DIARIOS'!$K$4:$K$508,'TOTALES MENSUALES'!A13) -> 0 | D13: =SUMIFS('TOTALES DIARIOS'!$H$4:$H$508,'TOTALES DIARIOS'!$L$4:$L$508,'TOTALES MENSUALES'!B13,'TOTALES DIARIOS'!$K$4:$K$508,'TOTALES MENSUALES'!A13) -> 0 | E13: =IF(C13>45,C13-45,0) -> 0 | F13: =F12+31 -> 45540
A14: =YEAR(F14) -> 2024 | B14: =MONTH(F14) -> 10 | C14: =SUMIFS('TOTALES DIARIOS'!$G$4:$G$508,'TOTALES DIARIOS'!$L$4:$L$508,'TOTALES MENSUALES'!B14,'TOTALES DIARIOS'!$K$4:$K$508,'TOTALES MENSUALES'!A14) -> 0 | D14: =SUMIFS('TOTALES DIARIOS'!$H$4:$H$508,'TOTALES DIARIOS'!$L$4:$L$508,'TOTALES MENSUALES'!B14,'TOTALES DIARIOS'!$K$4:$K$508,'TOTALES MENSUALES'!A14) -> 0 | E14: =IF(C14>45,C14-45,0) -> 0 | F14: =F13+31 -> 45571
A15: =YEAR(F15) -> 2024 | B15: =MONTH(F15) -> 11 | C15: =SUMIFS('TOTALES DIARIOS'!$G$4:$G$508,'TOTALES DIARIOS'!$L$4:$L$508,'TOTALES MENSUALES'!B15,'TOTALES DIARIOS'!$K$4:$K$508,'TOTALES MENSUALES'!A15) -> 0 | D15: =SUMIFS('TOTALES DIARIOS'!$H$4:$H$508,'TOTALES DIARIOS'!$L$4:$L$508,'TOTALES MENSUALES'!B15,'TOTALES DIARIOS'!$K$4:$K$508,'TOTALES MENSUALES'!A15) -> 0 | E15: =IF(C15>45,C15-45,0) -> 0 | F15: =F14+31 -> 45602
A16: =YEAR(F16) -> 2024 | B16: =MONTH(F16) -> 12 | C16: =SUMIFS('TOTALES DIARIOS'!$G$4:$G$508,'TOTALES DIARIOS'!$L$4:$L$508,'TOTALES MENSUALES'!B16,'TOTALES DIARIOS'!$K$4:$K$508,'TOTALES MENSUALES'!A16) -> 0 | D16: =SUMIFS('TOTALES DIARIOS'!$H$4:$H$508,'TOTALES DIARIOS'!$L$4:$L$508,'TOTALES MENSUALES'!B16,'TOTALES DIARIOS'!$K$4:$K$508,'TOTALES MENSUALES'!A16) -> 0 | E16: =IF(C16>45,C16-45,0) -> 0 | F16: =F15+31 -> 45633
A17: =YEAR(F17) -> 2025 | B17: =MONTH(F17) -> 1 | C17: =SUMIFS('TOTALES DIARIOS'!$G$4:$G$508,'TOTALES DIARIOS'!$L$4:$L$508,'TOTALES MENSUALES'!B17,'TOTALES DIARIOS'!$K$4:$K$508,'TOTALES MENSUALES'!A17) -> 0 | D17: =SUMIFS('TOTALES DIARIOS'!$H$4:$H$508,'TOTALES DIARIOS'!$L$4:$L$508,'TOTALES MENSUALES'!B17,'TOTALES DIARIOS'!$K$4:$K$508,'TOTALES MENSUALES'!A17) -> 0 | E17: =IF(C17>45,C17-45,0) -> 0 | F17: =F16+31 -> 45664
A18: =YEAR(F18) -> 2025 | B18: =MONTH(F18) -> 2 | C18: =SUMIFS('TOTALES DIARIOS'!$G$4:$G$508,'TOTALES DIARIOS'!$L$4:$L$508,'TOTALES MENSUALES'!B18,'TOTALES DIARIOS'!$K$4:$K$508,'TOTALES MENSUALES'!A18) -> 0 | D18: =SUMIFS('TOTALES DIARIOS'!$H$4:$H$508,'TOTALES DIARIOS'!$L$4:$L$508,'TOTALES MENSUALES'!B18,'TOTALES DIARIOS'!$K$4:$K$508,'TOTALES MENSUALES'!A18) -> 0 | E18: =IF(C18>45,C18-45,0) -> 0 | F18: =F17+31 -> 45695
... A40: =YEAR(F40) -> 2026 | B40: =MONTH(F40) -> 12 | C40: =SUMIFS('TOTALES DIARIOS'!$G$4:$G$508,'TOTALES DIARIOS'!$L$4:$L$508,'TOTALES MENSUALES'!B40,'TOTALES DIARIOS'!$K$4:$K$508,'TOTALES MENSUALES'!A40) -> 0 | D40: =SUMIFS('TOTALES DIARIOS'!$H$4:$H$508,'TOTALES DIARIOS'!$L$4:$L$508,'TOTALES MENSUALES'!B40,'TOTALES DIARIOS'!$K$4:$K$508,'TOTALES MENSUALES'!A40) -> 0 | E40: =IF(C40>45,C40-45,0) -> 0 | F40: =F39+31 -> 46377

Sheet TOTALES DIARIOS
A1: TOTALES DIARIOS
I2: columnas auxiliares | M2: Auxiliares | T2: Tabla de descansos | AA2: Diurnos | AC2: Nocturnos
A3: Fecha | B3: Horario Presentación | C3: Primer Despegue | D3: Último Aterrizaje | E3: TOTAL TV DIURNO | F3: TOTAL TV NOCTURNO | G3: Total TV | H3: Total TSV | I3: HUBO ACTIVIDAD | J3: Dias de servicios | K3: AÑO | L3: MES | M3: Min Despegue | N3: Min Despegue al proximo dia | O3: Primer aterrizaje del dia mayor al primer despegue | P3: MAX ATERRIZAJE MENOR AL DESPEGUE | Q3: Primer despegue | R3: Ultimo aterrizaje | S3: Aterrizaje Nocturno | T3: DURACIÓN DEL TIEMPO DE SERVICIO INMEDIATO PRECEDENTE | U3: DESCANSO EN BASE O FUERA DE BASE | V3: DESCANSO NOCTURNO NORMAL INTERRUMPIDO | Y3: Dia | Z3: Mes | AA3: Desde | AB3: Hasta | AC3: Desde | AD3: Hasta | AE3: Estacion
A4: =Consolidado!A6 -> 45292 | B4: =IF(G4=0,"",C4-"1:00") -> 0 | C4: =Q4 -> 0.041666667 | D4: =R4 -> 0.083333333 | E4: =SUMIF(Consolidado!$A$6:$A$380,'TOTALES DIARIOS'!A4,Consolidado!$E$6:$E$380) -> 0 | F4: =SUMIF(Consolidado!$A$6:$A$380,'TOTALES DIARIOS'!A4,Consolidado!$F$6:$F$380) -> 1.5 | G4: =SUMIF(Consolidado!$A$6:$A$380,'TOTALES DIARIOS'!A4,Consolidado!$G$6:$G$380) -> 1.5 | H4: =IF(B4="",0,IF(B4<D4,D4-B4+"0:30","24:00"-B4+D4+"0:30"))*24 -> 2.5 | I4: =IF(G4<>0,1,0) -> 1 | J4: =IF(H4=0,0,IF((D4-"3:30")>(C4-"3:30"),1,2)) -> 1 | K4: =YEAR(A4) -> 2024 | L4: =MONTH(A4) -> 1 | M4: {=MIN(IF(Consolidado!$A$6:$A$1000='TOTALES DIARIOS'!A4,IF(Consolidado!$C$6:$C$1000>TIMEVALUE("07:00"),Consolidado!$C$6:$C$1000,1)))} -> 1 | N4: {=MIN(IF(Consolidado!$A$6:$A$1000='TOTALES DIARIOS'!A4,IF(Consolidado!$C$6:$C$1000<=M4,Consolidado!$C$6:$C$1000,1)))} -> 0.041666667 | O4: {=MAX(IF(Consolidado!$A$6:$A$1000='TOTALES DIARIOS'!A4,IF(Consolidado!$D$6:$D$1000>=M4,Consolidado!$D$6:$D$1000,0)))} -> 0 | P4: {=MAX(IF(Consolidado!$A$6:$A$1000='TOTALES DIARIOS'!A4,IF(Consolidado!$D$6:$D$1000<=M4,Consolidado!$D$6:$D$1000,0)))} -> 0.083333333 | Q4: =IF(M4<>1,MAX(M4,N4),N4) -> 0.041666667 | R4: =IF(O4=0,P4,IF(P4=0,O4,MIN(P4,O4))) -> 0.083333333 | S4: =IF(D4>AB4,"SI","NO") -> NO | T4: 2 | U4: 8 | V4: 10 | Y4: =CONCATENATE(REPT("0",2-LEN(DAY(A4))),DAY(A4)) -> 01 | Z4: =CONCATENATE(REPT("0",2-LEN(MONTH(A4))),MONTH(A4)) -> 01 | AA4: =IFERROR(VLOOKUP(AE4,Parametros!$A$10:$G$13,4,0),0) -> 0.375 | AB4: =IFERROR(VLOOKUP(AE4,Parametros!$A$10:$G$13,5,0),0) -> 0.95833333 | AC4: =IFERROR(VLOOKUP(AE4,Parametros!$A$10:$G$13,6,0),0) -> 0.95902778 | AD4: =IFERROR(VLOOKUP(AE4,Parametros!$A$10:$G$13,7,0),0) -> 0.37430556 | AE4: =IF(AND(VALUE(CONCATENATE(Z4,Y4))>=Parametros!$B$11,VALUE(CONCATENATE(Z4,Y4))<=Parametros!$C$11),Parametros!$A$11,IF(AND(VALUE(CONCATENATE(Z4,Y4))>=Parametros!$B$12,VALUE(CONCATENATE(Z4,Y4))<=Parametros!$C$12),Parametros!$A$12,IF(AND(VALUE(CONCATENATE(Z4,Y4))>=Parametros!$B$13,VALUE(CONCATENATE(Z4,Y4))<=Parametros!$C$13),Parametros!$A$13,Parametros!$A$10))) -> Verano
A5: =IFERROR(A4+1,"") -> 45293 | B5: =IF(G5=0,"",C5-"1:00") | C5: =Q5 -> 0 | D5: =R5 -> 0 | E5: =SUMIF(Consolidado!$A$6:$A$380,'TOTALES DIARIOS'!A5,Consolidado!$E$6:$E$380) -> 0 | F5: =SUMIF(Consolidado!$A$6:$A$380,'TOTALES DIARIOS'!A5,Consolidado!$F$6:$F$380) -> 0 | G5: =SUMIF(Consolidado!$A$6:$A$380,'TOTALES DIARIOS'!A5,Consolidado!$G$6:$G$380) -> 0 | H5: =IF(B5="",0,IF(B5<D5,D5-B5+"0:30","24:00"-B5+D5+"0:30"))*24 -> 0 | I5: =IF(G5<>0,1,0) -> 0 | J5: =IF(H5=0,0,IF((D5-"3:30")>(C5-"3:30"),1,2)) -> 0 | K5: =YEAR(A5) -> 2024 | L5: =MONTH(A5) -> 1 | M5: {=MIN(IF(Consolidado!$A$6:$A$1000='TOTALES DIARIOS'!A5,IF(Consolidado!$C$6:$C$1000>TIMEVALUE("07:00"),Consolidado!$C$6:$C$1000,1)))} -> 0 | N5: {=MIN(IF(Consolidado!$A$6:$A$1000='TOTALES DIARIOS'!A5,IF(Consolidado!$C$6:$C$1000<=M5,Consolidado!$C$6:$C$1000,1)))} -> 0 | O5: {=MAX(IF(Consolidado!$A$6:$A$1000='TOTALES DIARIOS'!A5,IF(Consolidado!$D$6:$D$1000>=M5,Consolidado!$D$6:$D$1000,0)))} -> 0 | P5: {=MAX(IF(Consolidado!$A$6:$A$1000='TOTALES DIARIOS'!A5,IF(Consolidado!$D$6:$D$1000<=M5,Consolidado!$D$6:$D$1000,0)))} -> 0 | Q5: =IF(M5<>1,MAX(M5,N5),N5) -> 0 | R5: =IF(O5=0,P5,IF(P5=0,O5,MIN(P5,O5))) -> 0 | S5: =IF(D5>AB5,"SI","NO") -> NO | T5: 3 | U5: 8 | V5: 10 | Y5: =CONCATENATE(REPT("0",2-LEN(DAY(A5))),DAY(A5)) -> 02 | Z5: =CONCATENATE(REPT("0",2-LEN(MONTH(A5))),MONTH(A5)) -> 01 | AA5: =IFERROR(VLOOKUP(AE5,Parametros!$A$10:$G$13,4,0),0) -> 0.375 | AB5: =IFERROR(VLOOKUP(AE5,Parametros!$A$10:$G$13,5,0),0) -> 0.95833333 | AC5: =IFERROR(VLOOKUP(AE5,Parametros!$A$10:$G$13,6,0),0) -> 0.95902778 | AD5: =IFERROR(VLOOKUP(AE5,Parametros!$A$10:$G$13,7,0),0) -> 0.37430556 | AE5: =IF(AND(VALUE(CONCATENATE(Z5,Y5))>=Parametros!$B$11,VALUE(CONCATENATE(Z5,Y5))<=Parametros!$C$11),Parametros!$A$11,IF(AND(VALUE(CONCATENATE(Z5,Y5))>=Parametros!$B$12,VALUE(CONCATENATE(Z5,Y5))<=Parametros!$C$12),Parametros!$A$12,IF(AND(VALUE(CONCATENATE(Z5,Y5))>=Parametros!$B$13,VALUE(CONCATENATE(Z5,Y5))<=Parametros!$C$13),Parametros!$A$13,Parametros!$A$10))) -> Verano
A6: =IFERROR(A5+1,"") -> 45294 | B6: =IF(G6=0,"",C6-"1:00") | C6: =Q6 -> 0 | D6: =R6 -> 0 | E6: =SUMIF(Consolidado!$A$6:$A$380,'TOTALES DIARIOS'!A6,Consolidado!$E$6:$E$380) -> 0 | F6: =SUMIF(Consolidado!$A$6:$A$380,'TOTALES DIARIOS'!A6,Consolidado!$F$6:$F$380) -> 0 | G6: =SUMIF(Consolidado!$A$6:$A$380,'TOTALES DIARIOS'!A6,Consolidado!$G$6:$G$380) -> 0 | H6: =IF(B6="",0,IF(B6<D6,D6-B6+"0:30","24:00"-B6+D6+"0:30"))*24 -> 0 | I6: =IF(G6<>0,1,0) -> 0 | J6: =IF(H6=0,0,IF((D6-"3:30")>(C6-"3:30"),1,2)) -> 0 | K6: =YEAR(A6) -> 2024 | L6: =MONTH(A6) -> 1 | M6: {=MIN(IF(Consolidado!$A$6:$A$1000='TOTALES DIARIOS'!A6,IF(Consolidado!$C$6:$C$1000>TIMEVALUE("07:00"),Consolidado!$C$6:$C$1000,1)))} -> 0 | N6: {=MIN(IF(Consolidado!$A$6:$A$1000='TOTALES DIARIOS'!A6,IF(Consolidado!$C$6:$C$1000<=M6,Consolidado!$C$6:$C$1000,1)))} -> 0 | O6: {=MAX(IF(Consolidado!$A$6:$A$1000='TOTALES DIARIOS'!A6,IF(Consolidado!$D$6:$D$1000>=M6,Consolidado!$D$6:$D$1000,0)))} -> 0 | P6: {=MAX(IF(Consolidado!$A$6:$A$1000='TOTALES DIARIOS'!A6,IF(Consolidado!$D$6:$D$1000<=M6,Consolidado!$D$6:$D$1000,0)))} -> 0 | Q6: =IF(M6<>1,MAX(M6,N6),N6) -> 0 | R6: =IF(O6=0,P6,IF(P6=0,O6,MIN(P6,O6))) -> 0 | S6: =IF(D6>AB6,"SI","NO") -> NO | T6: 4 | U6: 8 | V6: 10 | Y6: =CONCATENATE(REPT("0",2-LEN(DAY(A6))),DAY(A6)) -> 03 | Z6: =CONCATENATE(REPT("0",2-LEN(MONTH(A6))),MONTH(A6)) -> 01 | AA6: =IFERROR(VLOOKUP(AE6,Parametros!$A$10:$G$13,4,0),0) -> 0.375 | AB6: =IFERROR(VLOOKUP(AE6,Parametros!$A$10:$G$13,5,0),0) -> 0.95833333 | AC6: =IFERROR(VLOOKUP(AE6,Parametros!$A$10:$G$13,6,0),0) -> 0.95902778 | AD6: =IFERROR(VLOOKUP(AE6,Parametros!$A$10:$G$13,7,0),0) -> 0.37430556 | AE6: =IF(AND(VALUE(CONCATENATE(Z6,Y6))>=Parametros!$B$11,VALUE(CONCATENATE(Z6,Y6))<=Parametros!$C$11),Parametros!$A$11,IF(AND(VALUE(CONCATENATE(Z6,Y6))>=Parametros!$B$12,VALUE(CONCATENATE(Z6,Y6))<=Parametros!$C$12),Parametros!$A$12,IF(AND(VALUE(CONCATENATE(Z6,Y6))>=Parametros!$B$13,VALUE(CONCATENATE(Z6,Y6))<=Parametros!$C$13),Parametros!$A$13,Parametros!$A$10))) -> Verano
A7: =IFERROR(A6+1,"") -> 45295 | B7: =IF(G7=0,"",C7-"1:00") | C7: =Q7 -> 0 | D7: =R7 -> 0 | E7: =SUMIF(Consolidado!$A$6:$A$380,'TOTALES DIARIOS'!A7,Consolidado!$E$6:$E$380) -> 0 | F7: =SUMIF(Consolidado!$A$6:$A$380,'TOTALES DIARIOS'!A7,Consolidado!$F$6:$F$380) -> 0 | G7: =SUMIF(Consolidado!$A$6:$A$380,'TOTALES DIARIOS'!A7,Consolidado!$G$6:$G$380) -> 0 | H7: =IF(B7="",0,IF(B7<D7,D7-B7+"0:30","24:00"-B7+D7+"0:30"))*24 -> 0 | I7: =IF(G7<>0,1,0) -> 0 | J7: =IF(H7=0,0,IF((D7-"3:30")>(C7-"3:30"),1,2)) -> 0 | K7: =YEAR(A7) -> 2024 | L7: =MONTH(A7) -> 1 | M7: {=MIN(IF(Consolidado!$A$6:$A$1000='TOTALES DIARIOS'!A7,IF(Consolidado!$C$6:$C$1000>TIMEVALUE("07:00"),Consolidado!$C$6:$C$1000,1)))} -> 0 | N7: {=MIN(IF(Consolidado!$A$6:$A$1000='TOTALES DIARIOS'!A7,IF(Consolidado!$C$6:$C$1000<=M7,Consolidado!$C$6:$C$1000,1)))} -> 0 | O7: {=MAX(IF(Consolidado!$A$6:$A$1000='TOTALES DIARIOS'!A7,IF(Consolidado!$D$6:$D$1000>=M7,Consolidado!$D$6:$D$1000,0)))} -> 0 | P7: {=MAX(IF(Consolidado!$A$6:$A$1000='TOTALES DIARIOS'!A7,IF(Consolidado!$D$6:$D$1000<=M7,Consolidado!$D$6:$D$1000,0)))} -> 0 | Q7: =IF(M7<>1,MAX(M7,N7),N7) -> 0 | R7: =IF(O7=0,P7,IF(P7=0,O7,MIN(P7,O7))) -> 0 | S7: =IF(D7>AB7,"SI","NO") -> NO | T7: 5 | U7: 8 | V7: 10 | Y7: =CONCATENATE(REPT("0",2-LEN(DAY(A7))),DAY(A7)) -> 04 | Z7: =CONCATENATE(REPT("0",2-LEN(MONTH(A7))),MONTH(A7)) -> 01 | AA7: =IFERROR(VLOOKUP(AE7,Parametros!$A$10:$G$13,4,0),0) -> 0.375 | AB7: =IFERROR(VLOOKUP(AE7,Parametros!$A$10:$G$13,5,0),0) -> 0.95833333 | AC7: =IFERROR(VLOOKUP(AE7,Parametros!$A$10:$G$13,6,0),0) -> 0.95902778 | AD7: =IFERROR(VLOOKUP(AE7,Parametros!$A$10:$G$13,7,0),0) -> 0.37430556 | AE7: =IF(AND(VALUE(CONCATENATE(Z7,Y7))>=Parametros!$B$11,VALUE(CONCATENATE(Z7,Y7))<=Parametros!$C$11),Parametros!$A$11,IF(AND(VALUE(CONCATENATE(Z7,Y7))>=Parametros!$B$12,VALUE(CONCATENATE(Z7,Y7))<=Parametros!$C$12),Parametros!$A$12,IF(AND(VALUE(CONCATENATE(Z7,Y7))>=Parametros!$B$13,VALUE(CONCATENATE(Z7,Y7))<=Parametros!$C$13),Parametros!$A$13,Parametros!$A$10))) -> Verano
A8: =IFERROR(A7+1,"") -> 45296 | B8: =IF(G8=0,"",C8-"1:00") | C8: =Q8 -> 0 | D8: =R8 -> 0 | E8: =SUMIF(Consolidado!$A$6:$A$380,'TOTALES DIARIOS'!A8,Consolidado!$E$6:$E$380) -> 0 | F8: =SUMIF(Consolidado!$A$6:$A$380,'TOTALES DIARIOS'!A8,Consolidado!$F$6:$F$380) -> 0 | G8: =SUMIF(Consolidado!$A$6:$A$380,'TOTALES DIARIOS'!A8,Consolidado!$G$6:$G$380) -> 0 | H8: =IF(B8="",0,IF(B8<D8,D8-B8+"0:30","24:00"-B8+D8+"0:30"))*24 -> 0 | I8: =IF(G8<>0,1,0) -> 0 | J8: =IF(H8=0,0,IF((D8-"3:30")>(C8-"3:30"),1,2)) -> 0 | K8: =YEAR(A8) -> 2024 | L8: =MONTH(A8) -> 1 | M8: {=MIN(IF(Consolidado!$A$6:$A$1000='TOTALES DIARIOS'!A8,IF(Consolidado!$C$6:$C$1000>TIMEVALUE("07:00"),Consolidado!$C$6:$C$1000,1)))} -> 0 | N8: {=MIN(IF(Consolidado!$A$6:$A$1000='TOTALES DIARIOS'!A8,IF(Consolidado!$C$6:$C$1000<=M8,Consolidado!$C$6:$C$1000,1)))} -> 0 | O8: {=MAX(IF(Consolidado!$A$6:$A$1000='TOTALES DIARIOS'!A8,IF(Consolidado!$D$6:$D$1000>=M8,Consolidado!$D$6:$D$1000,0)))} -> 0 | P8: {=MAX(IF(Consolidado!$A$6:$A$1000='TOTALES DIARIOS'!A8,IF(Consolidado!$D$6:$D$1000<=M8,Consolidado!$D$6:$D$1000,0)))} -> 0 | Q8: =IF(M8<>1,MAX(M8,N8),N8) -> 0 | R8: =IF(O8=0,P8,IF(P8=0,O8,MIN(P8,O8))) -> 0 | S8: =IF(D8>AB8,"SI","NO") -> NO | T8: 6 | U8: 8 | V8: 10 | Y8: =CONCATENATE(REPT("0",2-LEN(DAY(A8))),DAY(A8)) -> 05 | Z8: =CONCATENATE(REPT("0",2-LEN(MONTH(A8))),MONTH(A8)) -> 01 | AA8: =IFERROR(VLOOKUP(AE8,Parametros!$A$10:$G$13,4,0),0) -> 0.375 | AB8: =IFERROR(VLOOKUP(AE8,Parametros!$A$10:$G$13,5,0),0) -> 0.95833333 | AC8: =IFERROR(VLOOKUP(AE8,Parametros!$A$10:$G$13,6,0),0) -> 0.95902778 | AD8: =IFERROR(VLOOKUP(AE8,Parametros!$A$10:$G$13,7,0),0) -> 0.37430556 | AE8: =IF(AND(VALUE(CONCATENATE(Z8,Y8))>=Parametros!$B$11,VALUE(CONCATENATE(Z8,Y8))<=Parametros!$C$11),Parametros!$A$11,IF(AND(VALUE(CONCATENATE(Z8,Y8))>=Parametros!$B$12,VALUE(CONCATENATE(Z8,Y8))<=Parametros!$C$12),Parametros!$A$12,IF(AND(VALUE(CONCATENATE(Z8,Y8))>=Parametros!$B$13,VALUE(CONCATENATE(Z8,Y8))<=Parametros!$C$13),Parametros!$A$13,Parametros!$A$10))) -> Verano
A9: =IFERROR(A8+1,"") -> 45297 | B9: =IF(G9=0,"",C9-"1:00") | C9: =Q9 -> 0 | D9: =R9 -> 0 | E9: =SUMIF(Consolidado!$A$6:$A$380,'TOTALES DIARIOS'!A9,Consolidado!$E$6:$E$380) -> 0 | F9: =SUMIF(Consolidado!$A$6:$A$380,'TOTALES DIARIOS'!A9,Consolidado!$F$6:$F$380) -> 0 | G9: =SUMIF(Consolidado!$A$6:$A$380,'TOTALES DIARIOS'!A9,Consolidado!$G$6:$G$380) -> 0 | H9: =IF(B9="",0,IF(B9<D9,D9-B9+"0:30","24:00"-B9+D9+"0:30"))*24 -> 0 | I9: =IF(G9<>0,1,0) -> 0 | J9: =IF(H9=0,0,IF((D9-"3:30")>(C9-"3:30"),1,2)) -> 0 | K9: =YEAR(A9) -> 2024 | L9: =MONTH(A9) -> 1 | M9: {=MIN(IF(Consolidado!$A$6:$A$1000='TOTALES DIARIOS'!A9,IF(Consolidado!$C$6:$C$1000>TIMEVALUE("07:00"),Consolidado!$C$6:$C$1000,1)))} -> 0 | N9: {=MIN(IF(Consolidado!$A$6:$A$1000='TOTALES DIARIOS'!A9,IF(Consolidado!$C$6:$C$1000<=M9,Consolidado!$C$6:$C$1000,1)))} -> 0 | O9: {=MAX(IF(Consolidado!$A$6:$A$1000='TOTALES DIARIOS'!A9,IF(Consolidado!$D$6:$D$1000>=M9,Consolidado!$D$6:$D$1000,0)))} -> 0 | P9: {=MAX(IF(Consolidado!$A$6:$A$1000='TOTALES DIARIOS'!A9,IF(Consolidado!$D$6:$D$1000<=M9,Consolidado!$D$6:$D$1000,0)))} -> 0 | Q9: =IF(M9<>1,MAX(M9,N9),N9) -> 0 | R9: =IF(O9=0,P9,IF(P9=0,O9,MIN(P9,O9))) -> 0 | S9: =IF(D9>AB9,"SI","NO") -> NO | T9: 7 | U9: 10 | V9: 12 | Y9: =CONCATENATE(REPT("0",2-LEN(DAY(A9))),DAY(A9)) -> 06 | Z9: =CONCATENATE(REPT("0",2-LEN(MONTH(A9))),MONTH(A9)) -> 01 | AA9: =IFERROR(VLOOKUP(AE9,Parametros!$A$10:$G$13,4,0),0) -> 0.375 | AB9: =IFERROR(VLOOKUP(AE9,Parametros!$A$10:$G$13,5,0),0) -> 0.95833333 | AC9: =IFERROR(VLOOKUP(AE9,Parametros!$A$10:$G$13,6,0),0) -> 0.95902778 | AD9: =IFERROR(VLOOKUP(AE9,Parametros!$A$10:$G$13,7,0),0) -> 0.37430556 | AE9: =IF(AND(VALUE(CONCATENATE(Z9,Y9))>=Parametros!$B$11,VALUE(CONCATENATE(Z9,Y9))<=Parametros!$C$11),Parametros!$A$11,IF(AND(VALUE(CONCATENATE(Z9,Y9))>=Parametros!$B$12,VALUE(CONCATENATE(Z9,Y9))<=Parametros!$C$12),Parametros!$A$12,IF(AND(VALUE(CONCATENATE(Z9,Y9))>=Parametros!$B$13,VALUE(CONCATENATE(Z9,Y9))<=Parametros!$C$13),Parametros!$A$13,Parametros!$A$10))) -> Verano
A10: =IFERROR(A9+1,"") -> 45298 | B10: =IF(G10=0,"",C10-"1:00") | C10: =Q10 -> 0 | D10: =R10 -> 0 | E10: =SUMIF(Consolidado!$A$6:$A$380,'TOTALES DIARIOS'!A10,Consolidado!$E$6:$E$380) -> 0 | F10: =SUMIF(Consolidado!$A$6:$A$380,'TOTALES DIARIOS'!A10,Consolidado!$F$6:$F$380) -> 0 | G10: =SUMIF(Consolidado!$A$6:$A$380,'TOTALES DIARIOS'!A10,Consolidado!$G$6:$G$380) -> 0 | H10: =IF(B10="",0,IF(B10<D10,D10-B10+"0:30","24:00"-B10+D10+"0:30"))*24 -> 0 | I10: =IF(G10<>0,1,0) -> 0 | J10: =IF(H10=0,0,IF((D10-"3:30")>(C10-"3:30"),1,2)) -> 0 | K10: =YEAR(A10) -> 2024 | L10: =MONTH(A10) -> 1 | M10: {=MIN(IF(Consolidado!$A$6:$A$1000='TOTALES DIARIOS'!A10,IF(Consolidado!$C$6:$C$1000>TIMEVALUE("07:00"),Consolidado!$C$6:$C$1000,1)))} -> 0 | N10: {=MIN(IF(Consolidado!$A$6:$A$1000='TOTALES DIARIOS'!A10,IF(Consolidado!$C$6:$C$1000<=M10,Consolidado!$C$6:$C$1000,1)))} -> 0 | O10: {=MAX(IF(Consolidado!$A$6:$A$1000='TOTALES DIARIOS'!A10,IF(Consolidado!$D$6:$D$1000>=M10,Consolidado!$D$6:$D$1000,0)))} -> 0 | P10: {=MAX(IF(Consolidado!$A$6:$A$1000='TOTALES DIARIOS'!A10,IF(Consolidado!$D$6:$D$1000<=M10,Consolidado!$D$6:$D$1000,0)))} -> 0 | Q10: =IF(M10<>1,MAX(M10,N10),N10) -> 0 | R10: =IF(O10=0,P10,IF(P10=0,O10,MIN(P10,O10))) -> 0 | S10: =IF(D10>AB10,"SI","NO") -> NO | T10: 8 | U10: 10 | V10: 12 | Y10: =CONCATENATE(REPT("0",2-LEN(DAY(A10))),DAY(A10)) -> 07 | Z10: =CONCATENATE(REPT("0",2-LEN(MONTH(A10))),MONTH(A10)) -> 01 | AA10: =IFERROR(VLOOKUP(AE10,Parametros!$A$10:$G$13,4,0),0) -> 0.375 | AB10: =IFERROR(VLOOKUP(AE10,Parametros!$A$10:$G$13,5,0),0) -> 0.95833333 | AC10: =IFERROR(VLOOKUP(AE10,Parametros!$A$10:$G$13,6,0),0) -> 0.95902778 | AD10: =IFERROR(VLOOKUP(AE10,Parametros!$A$10:$G$13,7,0),0) -> 0.37430556 | AE10: =IF(AND(VALUE(CONCATENATE(Z10,Y10))>=Parametros!$B$11,VALUE(CONCATENATE(Z10,Y10))<=Parametros!$C$11),Parametros!$A$11,IF(AND(VALUE(CONCATENATE(Z10,Y10))>=Parametros!$B$12,VALUE(CONCATENATE(Z10,Y10))<=Parametros!$C$12),Parametros!$A$12,IF(AND(VALUE(CONCATENATE(Z10,Y10))>=Parametros!$B$13,VALUE(CONCATENATE(Z10,Y10))<=Parametros!$C$13),Parametros!$A$13,Parametros!$A$10))) -> Verano
A11: =IFERROR(A10+1,"") -> 45299 | B11: =IF(G11=0,"",C11-"1:00") | C11: =Q11 -> 0 | D11: =R11 -> 0 | E11: =SUMIF(Consolidado!$A$6:$A$380,'TOTALES DIARIOS'!A11,Consolidado!$E$6:$E$380) -> 0 | F11: =SUMIF(Consolidado!$A$6:$A$380,'TOTALES DIARIOS'!A11,Consolidado!$F$6:$F$380) -> 0 | G11: =SUMIF(Consolidado!$A$6:$A$380,'TOTALES DIARIOS'!A11,Consolidado!$G$6:$G$380) -> 0 | H11: =IF(B11="",0,IF(B11<D11,D11-B11+"0:30","24:00"-B11+D11+"0:30"))*24 -> 0 | I11: =IF(G11<>0,1,0) -> 0 | J11: =IF(H11=0,0,IF((D11-"3:30")>(C11-"3:30"),1,2)) -> 0 | K11: =YEAR(A11) -> 2024 | L11: =MONTH(A11) -> 1 | M11: {=MIN(IF(Consolidado!$A$6:$A$1000='TOTALES DIARIOS'!A11,IF(Consolidado!$C$6:$C$1000>TIMEVALUE("07:00"),Consolidado!$C$6:$C$1000,1)))} -> 0 | N11: {=MIN(IF(Consolidado!$A$6:$A$1000='TOTALES DIARIOS'!A11,IF(Consolidado!$C$6:$C$1000<=M11,Consolidado!$C$6:$C$1000,1)))} -> 0 | O11: {=MAX(IF(Consolidado!$A$6:$A$1000='TOTALES DIARIOS'!A11,IF(Consolidado!$D$6:$D$1000>=M11,Consolidado!$D$6:$D$1000,0)))} -> 0 | P11: {=MAX(IF(Consolidado!$A$6:$A$1000='TOTALES DIARIOS'!A11,IF(Consolidado!$D$6:$D$1000<=M11,Consolidado!$D$6:$D$1000,0)))} -> 0 | Q11: =IF(M11<>1,MAX(M11,N11),N11) -> 0 | R11: =IF(O11=0,P11,IF(P11=0,O11,MIN(P11,O11))) -> 0 | S11: =IF(D11>AB11,"SI","NO") -> NO | T11: 9 | U11: 11 | V11: 13 | Y11: =CONCATENATE(REPT("0",2-LEN(DAY(A11))),DAY(A11)) -> 08 | Z11: =CONCATENATE(REPT("0",2-LEN(MONTH(A11))),MONTH(A11)) -> 01 | AA11: =IFERROR(VLOOKUP(AE11,Parametros!$A$10:$G$13,4,0),0) -> 0.375 | AB11: =IFERROR(VLOOKUP(AE11,Parametros!$A$10:$G$13,5,0),0) -> 0.95833333 | AC11: =IFERROR(VLOOKUP(AE11,Parametros!$A$10:$G$13,6,0),0) -> 0.95902778 | AD11: =IFERROR(VLOOKUP(AE11,Parametros!$A$10:$G$13,7,0),0) -> 0.37430556 | AE11: =IF(AND(VALUE(CONCATENATE(Z11,Y11))>=Parametros!$B$11,VALUE(CONCATENATE(Z11,Y11))<=Parametros!$C$11),Parametros!$A$11,IF(AND(VALUE(CONCATENATE(Z11,Y11))>=Parametros!$B$12,VALUE(CONCATENATE(Z11,Y11))<=Parametros!$C$12),Parametros!$A$12,IF(AND(VALUE(CONCATENATE(Z11,Y11))>=Parametros!$B$13,VALUE(CONCATENATE(Z11,Y11))<=Parametros!$C$13),Parametros!$A$13,Parametros!$A$10))) -> Verano
A12: =IFERROR(A11+1,"") -> 45300 | B12: =IF(G12=0,"",C12-"1:00") | C12: =Q12 -> 0 | D12: =R12 -> 0 | E12: =SUMIF(Consolidado!$A$6:$A$380,'TOTALES DIARIOS'!A12,Consolidado!$E$6:$E$380) -> 0 | F12: =SUMIF(Consolidado!$A$6:$A$380,'TOTALES DIARIOS'!A12,Consolidado!$F$6:$F$380) -> 0 | G12: =SUMIF(Consolidado!$A$6:$A$380,'TOTALES DIARIOS'!A12,Consolidado!$G$6:$G$380) -> 0 | H12: =IF(B12="",0,IF(B12<D12,D12-B12+"0:30","24:00"-B12+D12+"0:30"))*24 -> 0 | I12: =IF(G12<>0,1,0) -> 0 | J12: =IF(H12=0,0,IF((D12-"3:30")>(C12-"3:30"),1,2)) -> 0 | K12: =YEAR(A12) -> 2024 | L12: =MONTH(A12) -> 1 | M12: {=MIN(IF(Consolidado!$A$6:$A$1000='TOTALES DIARIOS'!A12,IF(Consolidado!$C$6:$C$1000>TIMEVALUE("07:00"),Consolidado!$C$6:$C$1000,1)))} -> 0 | N12: {=MIN(IF(Consolidado!$A$6:$A$1000='TOTALES DIARIOS'!A12,IF(Consolidado!$C$6:$C$1000<=M12,Consolidado!$C$6:$C$1000,1)))} -> 0 | O12: {=MAX(IF(Consolidado!$A$6:$A$1000='TOTALES DIARIOS'!A12,IF(Consolidado!$D$6:$D$1000>=M12,Consolidado!$D$6:$D$1000,0)))} -> 0 | P12: {=MAX(IF(Consolidado!$A$6:$A$1000='TOTALES DIARIOS'!A12,IF(Consolidado!$D$6:$D$1000<=M12,Consolidado!$D$6:$D$1000,0)))} -> 0 | Q12: =IF(M12<>1,MAX(M12,N12),N12) -> 0 | R12: =IF(O12=0,P12,IF(P12=0,O12,MIN(P12,O12))) -> 0 | S12: =IF(D12>AB12,"SI","NO") -> NO | T12: 10 | U12: 12 | V12: 14 | Y12: =CONCATENATE(REPT("0",2-LEN(DAY(A12))),DAY(A12)) -> 09 | Z12: =CONCATENATE(REPT("0",2-LEN(MONTH(A12))),MONTH(A12)) -> 01 | AA12: =IFERROR(VLOOKUP(AE12,Parametros!$A$10:$G$13,4,0),0) -> 0.375 | AB12: =IFERROR(VLOOKUP(AE12,Parametros!$A$10:$G$13,5,0),0) -> 0.95833333 | AC12: =IFERROR(VLOOKUP(AE12,Parametros!$A$10:$G$13,6,0),0) -> 0.95902778 | AD12: =IFERROR(VLOOKUP(AE12,Parametros!$A$10:$G$13,7,0),0) -> 0.37430556 | AE12: =IF(AND(VALUE(CONCATENATE(Z12,Y12))>=Parametros!$B$11,VALUE(CONCATENATE(Z12,Y12))<=Parametros!$C$11),Parametros!$A$11,IF(AND(VALUE(CONCATENATE(Z12,Y12))>=Parametros!$B$12,VALUE(CONCATENATE(Z12,Y12))<=Parametros!$C$12),Parametros!$A$12,IF(AND(VALUE(CONCATENATE(Z12,Y12))>=Parametros!$B$13,VALUE(CONCATENATE(Z12,Y12))<=Parametros!$C$13),Parametros!$A$13,Parametros!$A$10))) -> Verano
A13: =IFERROR(A12+1,"") -> 45301 | B13: =IF(G13=0,"",C13-"1:00") | C13: =Q13 -> 0 | D13: =R13 -> 0 | E13: =SUMIF(Consolidado!$A$6:$A$380,'TOTALES DIARIOS'!A13,Consolidado!$E$6:$E$380) -> 0 | F13: =SUMIF(Consolidado!$A$6:$A$380,'TOTALES DIARIOS'!A13,Consolidado!$F$6:$F$380) -> 0 | G13: =SUMIF(Consolidado!$A$6:$A$380,'TOTALES DIARIOS'!A13,Consolidado!$G$6:$G$380) -> 0 | H13: =IF(B13="",0,IF(B13<D13,D13-B13+"0:30","24:00"-B13+D13+"0:30"))*24 -> 0 | I13: =IF(G13<>0,1,0) -> 0 | J13: =IF(H13=0,0,IF((D13-"3:30")>(C13-"3:30"),1,2)) -> 0 | K13: =YEAR(A13) -> 2024 | L13: =MONTH(A13) -> 1 | M13: {=MIN(IF(Consolidado!$A$6:$A$1000='TOTALES DIARIOS'!A13,IF(Consolidado!$C$6:$C$1000>TIMEVALUE("07:00"),Consolidado!$C$6:$C$1000,1)))} -> 0 | N13: {=MIN(IF(Consolidado!$A$6:$A$1000='TOTALES DIARIOS'!A13,IF(Consolidado!$C$6:$C$1000<=M13,Consolidado!$C$6:$C$1000,1)))} -> 0 | O13: {=MAX(IF(Consolidado!$A$6:$A$1000='TOTALES DIARIOS'!A13,IF(Consolidado!$D$6:$D$1000>=M13,Consolidado!$D$6:$D$1000,0)))} -> 0 | P13: {=MAX(IF(Consolidado!$A$6:$A$1000='TOTALES DIARIOS'!A13,IF(Consolidado!$D$6:$D$1000<=M13,Consolidado!$D$6:$D$1000,0)))} -> 0 | Q13: =IF(M13<>1,MAX(M13,N13),N13) -> 0 | R13: =IF(O13=0,P13,IF(P13=0,O13,MIN(P13,O13))) -> 0 | S13: =IF(D13>AB13,"SI","NO") -> NO | T13: 11 | U13: 13 | V13: 15 | Y13: =CONCATENATE(REPT("0",2-LEN(DAY(A13))),DAY(A13)) -> 10 | Z13: =CONCATENATE(REPT("0",2-LEN(MONTH(A13))),MONTH(A13)) -> 01 | AA13: =IFERROR(VLOOKUP(AE13,Parametros!$A$10:$G$13,4,0),0) -> 0.375 | AB13: =IFERROR(VLOOKUP(AE13,Parametros!$A$10:$G$13,5,0),0) -> 0.95833333 | AC13: =IFERROR(VLOOKUP(AE13,Parametros!$A$10:$G$13,6,0),0) -> 0.95902778 | AD13: =IFERROR(VLOOKUP(AE13,Parametros!$A$10:$G$13,7,0),0) -> 0.37430556 | AE13: =IF(AND(VALUE(CONCATENATE(Z13,Y13))>=Parametros!$B$11,VALUE(CONCATENATE(Z13,Y13))<=Parametros!$C$11),Parametros!$A$11,IF(AND(VALUE(CONCATENATE(Z13,Y13))>=Parametros!$B$12,VALUE(CONCATENATE(Z13,Y13))<=Parametros!$C$12),Parametros!$A$12,IF(AND(VALUE(CONCATENATE(Z13,Y13))>=Parametros!$B$13,VALUE(CONCATENATE(Z13,Y13))<=Parametros!$C$13),Parametros!$A$13,Parametros!$A$10))) -> Verano
A14: =IFERROR(A13+1,"") -> 45302 | B14: =IF(G14=0,"",C14-"1:00") | C14: =Q14 -> 0 | D14: =R14 -> 0 | E14: =SUMIF(Consolidado!$A$6:$A$380,'TOTALES DIARIOS'!A14,Consolidado!$E$6:$E$380) -> 0 | F14: =SUMIF(Consolidado!$A$6:$A$380,'TOTALES DIARIOS'!A14,Consolidado!$F$6:$F$380) -> 0 | G14: =SUMIF(Consolidado!$A$6:$A$380,'TOTALES DIARIOS'!A14,Consolidado!$G$6:$G$380) -> 0 | H14: =IF(B14="",0,IF(B14<D14,D14-B14+"0:30","24:00"-B14+D14+"0:30"))*24 -> 0 | I14: =IF(G14<>0,1,0) -> 0 | J14: =IF(H14=0,0,IF((D14-"3:30")>(C14-"3:30"),1,2)) -> 0 | K14: =YEAR(A14) -> 2024 | L14: =MONTH(A14) -> 1 | M14: {=MIN(IF(Consolidado!$A$6:$A$1000='TOTALES DIARIOS'!A14,IF(Consolidado!$C$6:$C$1000>TIMEVALUE("07:00"),Consolidado!$C$6:$C$1000,1)))} -> 0 | N14: {=MIN(IF(Consolidado!$A$6:$A$1000='TOTALES DIARIOS'!A14,IF(Consolidado!$C$6:$C$1000<=M14,Consolidado!$C$6:$C$1000,1)))} -> 0 | O14: {=MAX(IF(Consolidado!$A$6:$A$1000='TOTALES DIARIOS'!A14,IF(Consolidado!$D$6:$D$1000>=M14,Consolidado!$D$6:$D$1000,0)))} -> 0 | P14: {=MAX(IF(Consolidado!$A$6:$A$1000='TOTALES DIARIOS'!A14,IF(Consolidado!$D$6:$D$1000<=M14,Consolidado!$D$6:$D$1000,0)))} -> 0 | Q14: =IF(M14<>1,MAX(M14,N14),N14) -> 0 | R14: =IF(O14=0,P14,IF(P14=0,O14,MIN(P14,O14))) -> 0 | S14: =IF(D14>AB14,"SI","NO") -> NO | T14: 12 | U14: 14 | V14: 16 | Y14: =CONCATENATE(REPT("0",2-LEN(DAY(A14))),DAY(A14)) -> 11 | Z14: =CONCATENATE(REPT("0",2-LEN(MONTH(A14))),MONTH(A14)) -> 01 | AA14: =IFERROR(VLOOKUP(AE14,Parametros!$A$10:$G$13,4,0),0) -> 0.375 | AB14: =IFERROR(VLOOKUP(AE14,Parametros!$A$10:$G$13,5,0),0) -> 0.95833333 | AC14: =IFERROR(VLOOKUP(AE14,Parametros!$A$10:$G$13,6,0),0) -> 0.95902778 | AD14: =IFERROR(VLOOKUP(AE14,Parametros!$A$10:$G$13,7,0),0) -> 0.37430556 | AE14: =IF(AND(VALUE(CONCATENATE(Z14,Y14))>=Parametros!$B$11,VALUE(CONCATENATE(Z14,Y14))<=Parametros!$C$11),Parametros!$A$11,IF(AND(VALUE(CONCATENATE(Z14,Y14))>=Parametros!$B$12,VALUE(CONCATENATE(Z14,Y14))<=Parametros!$C$12),Parametros!$A$12,IF(AND(VALUE(CONCATENATE(Z14,Y14))>=Parametros!$B$13,VALUE(CONCATENATE(Z14,Y14))<=Parametros!$C$13),Parametros!$A$13,Parametros!$A$10))) -> Verano
A15: =IFERROR(A14+1,"") -> 45303 | B15: =IF(G15=0,"",C15-"1:00") | C15: =Q15 -> 0 | D15: =R15 -> 0 | E15: =SUMIF(Consolidado!$A$6:$A$380,'TOTALES DIARIOS'!A15,Consolidado!$E$6:$E$380) -> 0 | F15: =SUMIF(Consolidado!$A$6:$A$380,'TOTALES DIARIOS'!A15,Consolidado!$F$6:$F$380) -> 0 | G15: =SUMIF(Consolidado!$A$6:$A$380,'TOTALES DIARIOS'!A15,Consolidado!$G$6:$G$380) -> 0 | H15: =IF(B15="",0,IF(B15<D15,D15-B15+"0:30","24:00"-B15+D15+"0:30"))*24 -> 0 | I15: =IF(G15<>0,1,0) -> 0 | J15: =IF(H15=0,0,IF((D15-"3:30")>(C15-"3:30"),1,2)) -> 0 | K15: =YEAR(A15) -> 2024 | L15: =MONTH(A15) -> 1 | M15: {=MIN(IF(Consolidado!$A$6:$A$1000='TOTALES DIARIOS'!A15,IF(Consolidado!$C$6:$C$1000>TIMEVALUE("07:00"),Consolidado!$C$6:$C$1000,1)))} -> 0 | N15: {=MIN(IF(Consolidado!$A$6:$A$1000='TOTALES DIARIOS'!A15,IF(Consolidado!$C$6:$C$1000<=M15,Consolidado!$C$6:$C$1000,1)))} -> 0 | O15: {=MAX(IF(Consolidado!$A$6:$A$1000='TOTALES DIARIOS'!A15,IF(Consolidado!$D$6:$D$1000>=M15,Consolidado!$D$6:$D$1000,0)))} -> 0 | P15: {=MAX(IF(Consolidado!$A$6:$A$1000='TOTALES DIARIOS'!A15,IF(Consolidado!$D$6:$D$1000<=M15,Consolidado!$D$6:$D$1000,0)))} -> 0 | Q15: =IF(M15<>1,MAX(M15,N15),N15) -> 0 | R15: =IF(O15=0,P15,IF(P15=0,O15,MIN(P15,O15))) -> 0 | S15: =IF(D15>AB15,"SI","NO") -> NO | T15: 13 | U15: 15 | V15: 16 | Y15: =CONCATENATE(REPT("0",2-LEN(DAY(A15))),DAY(A15)) -> 12 | Z15: =CONCATENATE(REPT("0",2-LEN(MONTH(A15))),MONTH(A15)) -> 01 | AA15: =IFERROR(VLOOKUP(AE15,Parametros!$A$10:$G$13,4,0),0) -> 0.375 | AB15: =IFERROR(VLOOKUP(AE15,Parametros!$A$10:$G$13,5,0),0) -> 0.95833333 | AC15: =IFERROR(VLOOKUP(AE15,Parametros!$A$10:$G$13,6,0),0) -> 0.95902778 | AD15: =IFERROR(VLOOKUP(AE15,Parametros!$A$10:$G$13,7,0),0) -> 0.37430556 | AE15: =IF(AND(VALUE(CONCATENATE(Z15,Y15))>=Parametros!$B$11,VALUE(CONCATENATE(Z15,Y15))<=Parametros!$C$11),Parametros!$A$11,IF(AND(VALUE(CONCATENATE(Z15,Y15))>=Parametros!$B$12,VALUE(CONCATENATE(Z15,Y15))<=Parametros!$C$12),Parametros!$A$12,IF(AND(VALUE(CONCATENATE(Z15,Y15))>=Parametros!$B$13,VALUE(CONCATENATE(Z15,Y15))<=Parametros!$C$13),Parametros!$A$13,Parametros!$A$10))) -> Verano
A16: =IFERROR(A15+1,"") -> 45304 | B16: =IF(G16=0,"",C16-"1:00") | C16: =Q16 -> 0 | D16: =R16 -> 0 | E16: =SUMIF(Consolidado!$A$6:$A$380,'TOTALES DIARIOS'!A16,Consolidado!$E$6:$E$380) -> 0 | F16: =SUMIF(Consolidado!$A$6:$A$380,'TOTALES DIARIOS'!A16,Consolidado!$F$6:$F$380) -> 0 | G16: =SUMIF(Consolidado!$A$6:$A$380,'TOTALES DIARIOS'!A16,Consolidado!$G$6:$G$380) -> 0 | H16: =IF(B16="",0,IF(B16<D16,D16-B16+"0:30","24:00"-B16+D16+"0:30"))*24 -> 0 | I16: =IF(G16<>0,1,0) -> 0 | J16: =IF(H16=0,0,IF((D16-"3:30")>(C16-"3:30"),1,2)) -> 0 | K16: =YEAR(A16) -> 2024 | L16: =MONTH(A16) -> 1 | M16: {=MIN(IF(Consolidado!$A$6:$A$1000='TOTALES DIARIOS'!A16,IF(Consolidado!$C$6:$C$1000>TIMEVALUE("07:00"),Consolidado!$C$6:$C$1000,1)))} -> 0 | N16: {=MIN(IF(Consolidado!$A$6:$A$1000='TOTALES DIARIOS'!A16,IF(Consolidado!$C$6:$C$1000<=M16,Consolidado!$C$6:$C$1000,1)))} -> 0 | O16: {=MAX(IF(Consolidado!$A$6:$A$1000='TOTALES DIARIOS'!A16,IF(Consolidado!$D$6:$D$1000>=M16,Consolidado!$D$6:$D$1000,0)))} -> 0 | P16: {=MAX(IF(Consolidado!$A$6:$A$1000='TOTALES DIARIOS'!A16,IF(Consolidado!$D$6:$D$1000<=M16,Consolidado!$D$6:$D$1000,0)))} -> 0 | Q16: =IF(M16<>1,MAX(M16,N16),N16) -> 0 | R16: =IF(O16=0,P16,IF(P16=0,O16,MIN(P16,O16))) -> 0 | S16: =IF(D16>AB16,"SI","NO") -> NO | T16: 14 | U16: 16 | V16: 17 | Y16: =CONCATENATE(REPT("0",2-LEN(DAY(A16))),DAY(A16)) -> 13 | Z16: =CONCATENATE(REPT("0",2-LEN(MONTH(A16))),MONTH(A16)) -> 01 | AA16: =IFERROR(VLOOKUP(AE16,Parametros!$A$10:$G$13,4,0),0) -> 0.375 | AB16: =IFERROR(VLOOKUP(AE16,Parametros!$A$10:$G$13,5,0),0) -> 0.95833333 | AC16: =IFERROR(VLOOKUP(AE16,Parametros!$A$10:$G$13,6,0),0) -> 0.95902778 | AD16: =IFERROR(VLOOKUP(AE16,Parametros!$A$10:$G$13,7,0),0) -> 0.37430556 | AE16: =IF(AND(VALUE(CONCATENATE(Z16,Y16))>=Parametros!$B$11,VALUE(CONCATENATE(Z16,Y16))<=Parametros!$C$11),Parametros!$A$11,IF(AND(VALUE(CONCATENATE(Z16,Y16))>=Parametros!$B$12,VALUE(CONCATENATE(Z16,Y16))<=Parametros!$C$12),Parametros!$A$12,IF(AND(VALUE(CONCATENATE(Z16,Y16))>=Parametros!$B$13,VALUE(CONCATENATE(Z16,Y16))<=Parametros!$C$13),Parametros!$A$13,Parametros!$A$10))) -> Verano
... A18: =IFERROR(A17+1,"") -> 45306 | B18: =IF(G18=0,"",C18-"1:00") | C18: =Q18 -> 0 | D18: =R18 -> 0 | E18: =SUMIF(Consolidado!$A$6:$A$380,'TOTALES DIARIOS'!A18,Consolidado!$E$6:$E$380) -> 0 | F18: =SUMIF(Consolidado!$A$6:$A$380,'TOTALES DIARIOS'!A18,Consolidado!$F$6:$F$380) -> 0 | G18: =SUMIF(Consolidado!$A$6:$A$380,'TOTALES DIARIOS'!A18,Consolidado!$G$6:$G$380) -> 0 | H18: =IF(B18="",0,IF(B18<D18,D18-B18+"0:30","24:00"-B18+D18+"0:30"))*24 -> 0 | I18: =IF(G18<>0,1,0) -> 0 | J18: =IF(H18=0,0,IF((D18-"3:30")>(C18-"3:30"),1,2)) -> 0 | K18: =YEAR(A18) -> 2024 | L18: =MONTH(A18) -> 1 | M18: {=MIN(IF(Consolidado!$A$6:$A$1000='TOTALES DIARIOS'!A18,IF(Consolidado!$C$6:$C$1000>TIMEVALUE("07:00"),Consolidado!$C$6:$C$1000,1)))} -> 0 | N18: {=MIN(IF(Consolidado!$A$6:$A$1000='TOTALES DIARIOS'!A18,IF(Consolidado!$C$6:$C$1000<=M18,Consolidado!$C$6:$C$1000,1)))} -> 0 | O18: {=MAX(IF(Consolidado!$A$6:$A$1000='TOTALES DIARIOS'!A18,IF(Consolidado!$D$6:$D$1000>=M18,Consolidado!$D$6:$D$1000,0)))} -> 0 | P18: {=MAX(IF(Consolidado!$A$6:$A$1000='TOTALES DIARIOS'!A18,IF(Consolidado!$D$6:$D$1000<=M18,Consolidado!$D$6:$D$1000,0)))} -> 0 | Q18: =IF(M18<>1,MAX(M18,N18),N18) -> 0 | R18: =IF(O18=0,P18,IF(P18=0,O18,MIN(P18,O18))) -> 0 | S18: =IF(D18>AB18,"SI","NO") -> NO | T18: 16 | U18: 18 | V18: 18 | Y18: =CONCATENATE(REPT("0",2-LEN(DAY(A18))),DAY(A18)) -> 15 | Z18: =CONCATENATE(REPT("0",2-LEN(MONTH(A18))),MONTH(A18)) -> 01 | AA18: =IFERROR(VLOOKUP(AE18,Parametros!$A$10:$G$13,4,0),0) -> 0.375 | AB18: =IFERROR(VLOOKUP(AE18,Parametros!$A$10:$G$13,5,0),0) -> 0.95833333 | AC18: =IFERROR(VLOOKUP(AE18,Parametros!$A$10:$G$13,6,0),0) -> 0.95902778 | AD18: =IFERROR(VLOOKUP(AE18,Parametros!$A$10:$G$13,7,0),0) -> 0.37430556 | AE18: =IF(AND(VALUE(CONCATENATE(Z18,Y18))>=Parametros!$B$11,VALUE(CONCATENATE(Z18,Y18))<=Parametros!$C$11),Parametros!$A$11,IF(AND(VALUE(CONCATENATE(Z18,Y18))>=Parametros!$B$12,VALUE(CONCATENATE(Z18,Y18))<=Parametros!$C$12),Parametros!$A$12,IF(AND(VALUE(CONCATENATE(Z18,Y18))>=Parametros!$B$13,VALUE(CONCATENATE(Z18,Y18))<=Parametros!$C$13),Parametros!$A$13,Parametros!$A$10))) -> Verano
A19: =IFERROR(A18+1,"") -> 45307 | B19: =IF(G19=0,"",C19-"1:00") | C19: =Q19 -> 0 | D19: =R19 -> 0 | E19: =SUMIF(Consolidado!$A$6:$A$380,'TOTALES DIARIOS'!A19,Consolidado!$E$6:$E$380) -> 0 | F19: =SUMIF(Consolidado!$A$6:$A$380,'TOTALES DIARIOS'!A19,Consolidado!$F$6:$F$380) -> 0 | G19: =SUMIF(Consolidado!$A$6:$A$380,'TOTALES DIARIOS'!A19,Consolidado!$G$6:$G$380) -> 0 | H19: =IF(B19="",0,IF(B19<D19,D19-B19+"0:30","24:00"-B19+D19+"0:30"))*24 -> 0 | I19: =IF(G19<>0,1,0) -> 0 | J19: =IF(H19=0,0,IF((D19-"3:30")>(C19-"3:30"),1,2)) -> 0 | K19: =YEAR(A19) -> 2024 | L19: =MONTH(A19) -> 1 | M19: {=MIN(IF(Consolidado!$A$6:$A$1000='TOTALES DIARIOS'!A19,IF(Consolidado!$C$6:$C$1000>TIMEVALUE("07:00"),Consolidado!$C$6:$C$1000,1)))} -> 0 | N19: {=MIN(IF(Consolidado!$A$6:$A$1000='TOTALES DIARIOS'!A19,IF(Consolidado!$C$6:$C$1000<=M19,Consolidado!$C$6:$C$1000,1)))} -> 0 | O19: {=MAX(IF(Consolidado!$A$6:$A$1000='TOTALES DIARIOS'!A19,IF(Consolidado!$D$6:$D$1000>=M19,Consolidado!$D$6:$D$1000,0)))} -> 0 | P19: {=MAX(IF(Consolidado!$A$6:$A$1000='TOTALES DIARIOS'!A19,IF(Consolidado!$D$6:$D$1000<=M19,Consolidado!$D$6:$D$1000,0)))} -> 0 | Q19: =IF(M19<>1,MAX(M19,N19),N19) -> 0 | R19: =IF(O19=0,P19,IF(P19=0,O19,MIN(P19,O19))) -> 0 | S19: =IF(D19>AB19,"SI","NO") -> NO | T19: 17 | U19: 20 | V19: 20
A20: =IFERROR(A19+1,"") -> 45308 | B20: =IF(G20=0,"",C20-"1:00") | C20: =Q20 -> 0 | D20: =R20 -> 0 | E20: =SUMIF(Consolidado!$A$6:$A$380,'TOTALES DIARIOS'!A20,Consolidado!$E$6:$E$380) -> 0 | F20: =SUMIF(Consolidado!$A$6:$A$380,'TOTALES DIARIOS'!A20,Consolidado!$F$6:$F$380) -> 0 | G20: =SUMIF(Consolidado!$A$6:$A$380,'TOTALES DIARIOS'!A20,Consolidado!$G$6:$G$380) -> 0 | H20: =IF(B20="",0,IF(B20<D20,D20-B20+"0:30","24:00"-B20+D20+"0:30"))*24 -> 0 | I20: =IF(G20<>0,1,0) -> 0 | J20: =IF(H20=0,0,IF((D20-"3:30")>(C20-"3:30"),1,2)) -> 0 | K20: =YEAR(A20) -> 2024 | L20: =MONTH(A20) -> 1 | M20: {=MIN(IF(Consolidado!$A$6:$A$1000='TOTALES DIARIOS'!A20,IF(Consolidado!$C$6:$C$1000>TIMEVALUE("07:00"),Consolidado!$C$6:$C$1000,1)))} -> 0 | N20: {=MIN(IF(Consolidado!$A$6:$A$1000='TOTALES DIARIOS'!A20,IF(Consolidado!$C$6:$C$1000<=M20,Consolidado!$C$6:$C$1000,1)))} -> 0 | O20: {=MAX(IF(Consolidado!$A$6:$A$1000='TOTALES DIARIOS'!A20,IF(Consolidado!$D$6:$D$1000>=M20,Consolidado!$D$6:$D$1000,0)))} -> 0 | P20: {=MAX(IF(Consolidado!$A$6:$A$1000='TOTALES DIARIOS'!A20,IF(Consolidado!$D$6:$D$1000<=M20,Consolidado!$D$6:$D$1000,0)))} -> 0 | Q20: =IF(M20<>1,MAX(M20,N20),N20) -> 0 | R20: =IF(O20=0,P20,IF(P20=0,O20,MIN(P20,O20))) -> 0 | S20: =IF(D20>AB20,"SI","NO") -> NO | T20: 18 | U20: 22 | V20: 22
A21: =IFERROR(A20+1,"") -> 45309 | B21: =IF(G21=0,"",C21-"1:00") | C21: =Q21 -> 0 | D21: =R21 -> 0 | E21: =SUMIF(Consolidado!$A$6:$A$380,'TOTALES DIARIOS'!A21,Consolidado!$E$6:$E$380) -> 0 | F21: =SUMIF(Consolidado!$A$6:$A$380,'TOTALES DIARIOS'!A21,Consolidado!$F$6:$F$380) -> 0 | G21: =SUMIF(Consolidado!$A$6:$A$380,'TOTALES DIARIOS'!A21,Consolidado!$G$6:$G$380) -> 0 | H21: =IF(B21="",0,IF(B21<D21,D21-B21+"0:30","24:00"-B21+D21+"0:30"))*24 -> 0 | I21: =IF(G21<>0,1,0) -> 0 | J21: =IF(H21=0,0,IF((D21-"3:30")>(C21-"3:30"),1,2)) -> 0 | K21: =YEAR(A21) -> 2024 | L21: =MONTH(A21) -> 1 | M21: {=MIN(IF(Consolidado!$A$6:$A$1000='TOTALES DIARIOS'!A21,IF(Consolidado!$C$6:$C$1000>TIMEVALUE("07:00"),Consolidado!$C$6:$C$1000,1)))} -> 0 | N21: {=MIN(IF(Consolidado!$A$6:$A$1000='TOTALES DIARIOS'!A21,IF(Consolidado!$C$6:$C$1000<=M21,Consolidado!$C$6:$C$1000,1)))} -> 0 | O21: {=MAX(IF(Consolidado!$A$6:$A$1000='TOTALES DIARIOS'!A21,IF(Consolidado!$D$6:$D$1000>=M21,Consolidado!$D$6:$D$1000,0)))} -> 0 | P21: {=MAX(IF(Consolidado!$A$6:$A$1000='TOTALES DIARIOS'!A21,IF(Consolidado!$D$6:$D$1000<=M21,Consolidado!$D$6:$D$1000,0)))} -> 0 | Q21: =IF(M21<>1,MAX(M21,N21),N21) -> 0 | R21: =IF(O21=0,P21,IF(P21=0,O21,MIN(P21,O21))) -> 0 | S21: =IF(D21>AB21,"SI","NO") -> NO | T21: 19 | U21: 24 | V21: 24
A22: =IFERROR(A21+1,"") -> 45310 | B22: =IF(G22=0,"",C22-"1:00") | C22: =Q22 -> 0 | D22: =R22 -> 0 | E22: =SUMIF(Consolidado!$A$6:$A$380,'TOTALES DIARIOS'!A22,Consolidado!$E$6:$E$380) -> 0 | F22: =SUMIF(Consolidado!$A$6:$A$380,'TOTALES DIARIOS'!A22,Consolidado!$F$6:$F$380) -> 0 | G22: =SUMIF(Consolidado!$A$6:$A$380,'TOTALES DIARIOS'!A22,Consolidado!$G$6:$G$380) -> 0 | H22: =IF(B22="",0,IF(B22<D22,D22-B22+"0:30","24:00"-B22+D22+"0:30"))*24 -> 0 | I22: =IF(G22<>0,1,0) -> 0 | J22: =IF(H22=0,0,IF((D22-"3:30")>(C22-"3:30"),1,2)) -> 0 | K22: =YEAR(A22) -> 2024 | L22: =MONTH(A22) -> 1 | M22: {=MIN(IF(Consolidado!$A$6:$A$1000='TOTALES DIARIOS'!A22,IF(Consolidado!$C$6:$C$1000>TIMEVALUE("07:00"),Consolidado!$C$6:$C$1000,1)))} -> 0 | N22: {=MIN(IF(Consolidado!$A$6:$A$1000='TOTALES DIARIOS'!A22,IF(Consolidado!$C$6:$C$1000<=M22,Consolidado!$C$6:$C$1000,1)))} -> 0 | O22: {=MAX(IF(Consolidado!$A$6:$A$1000='TOTALES DIARIOS'!A22,IF(Consolidado!$D$6:$D$1000>=M22,Consolidado!$D$6:$D$1000,0)))} -> 0 | P22: {=MAX(IF(Consolidado!$A$6:$A$1000='TOTALES DIARIOS'!A22,IF(Consolidado!$D$6:$D$1000<=M22,Consolidado!$D$6:$D$1000,0)))} -> 0 | Q22: =IF(M22<>1,MAX(M22,N22),N22) -> 0 | R22: =IF(O22=0,P22,IF(P22=0,O22,MIN(P22,O22))) -> 0 | S22: =IF(D22>AB22,"SI","NO") -> NO | T22: 20 | U22: 26 | V22: 26
A23: =IFERROR(A22+1,"") -> 45311 | B23: =IF(G23=0,"",C23-"1:00") | C23: =Q23 -> 0 | D23: =R23 -> 0 | E23: =SUMIF(Consolidado!$A$6:$A$380,'TOTALES DIARIOS'!A23,Consolidado!$E$6:$E$380) -> 0 | F23: =SUMIF(Consolidado!$A$6:$A$380,'TOTALES DIARIOS'!A23,Consolidado!$F$6:$F$380) -> 0 | G23: =SUMIF(Consolidado!$A$6:$A$380,'TOTALES DIARIOS'!A23,Consolidado!$G$6:$G$380) -> 0 | H23: =IF(B23="",0,IF(B23<D23,D23-B23+"0:30","24:00"-B23+D23+"0:30"))*24 -> 0 | I23: =IF(G23<>0,1,0) -> 0 | J23: =IF(H23=0,0,IF((D23-"3:30")>(C23-"3:30"),1,2)) -> 0 | K23: =YEAR(A23) -> 2024 | L23: =MONTH(A23) -> 1 | M23: {=MIN(IF(Consolidado!$A$6:$A$1000='TOTALES DIARIOS'!A23,IF(Consolidado!$C$6:$C$1000>TIMEVALUE("07:00"),Consolidado!$C$6:$C$1000,1)))} -> 0 | N23: {=MIN(IF(Consolidado!$A$6:$A$1000='TOTALES DIARIOS'!A23,IF(Consolidado!$C$6:$C$1000<=M23,Consolidado!$C$6:$C$1000,1)))} -> 0 | O23: {=MAX(IF(Consolidado!$A$6:$A$1000='TOTALES DIARIOS'!A23,IF(Consolidado!$D$6:$D$1000>=M23,Consolidado!$D$6:$D$1000,0)))} -> 0 | P23: {=MAX(IF(Consolidado!$A$6:$A$1000='TOTALES DIARIOS'!A23,IF(Consolidado!$D$6:$D$1000<=M23,Consolidado!$D$6:$D$1000,0)))} -> 0 | Q23: =IF(M23<>1,MAX(M23,N23),N23) -> 0 | R23: =IF(O23=0,P23,IF(P23=0,O23,MIN(P23,O23))) -> 0 | S23: =IF(D23>AB23,"SI","NO") -> NO | T23: 21 | U23: 28 | V23: 28
A24: =IFERROR(A23+1,"") -> 45312 | B24: =IF(G24=0,"",C24-"1:00") | C24: =Q24 -> 0 | D24: =R24 -> 0 | E24: =SUMIF(Consolidado!$A$6:$A$380,'TOTALES DIARIOS'!A24,Consolidado!$E$6:$E$380) -> 0 | F24: =SUMIF(Consolidado!$A$6:$A$380,'TOTALES DIARIOS'!A24,Consolidado!$F$6:$F$380) -> 0 | G24: =SUMIF(Consolidado!$A$6:$A$380,'TOTALES DIARIOS'!A24,Consolidado!$G$6:$G$380) -> 0 | H24: =IF(B24="",0,IF(B24<D24,D24-B24+"0:30","24:00"-B24+D24+"0:30"))*24 -> 0 | I24: =IF(G24<>0,1,0) -> 0 | J24: =IF(H24=0,0,IF((D24-"3:30")>(C24-"3:30"),1,2)) -> 0 | K24: =YEAR(A24) -> 2024 | L24: =MONTH(A24) -> 1 | M24: {=MIN(IF(Consolidado!$A$6:$A$1000='TOTALES DIARIOS'!A24,IF(Consolidado!$C$6:$C$1000>TIMEVALUE("07:00"),Consolidado!$C$6:$C$1000,1)))} -> 0 | N24: {=MIN(IF(Consolidado!$A$6:$A$1000='TOTALES DIARIOS'!A24,IF(Consolidado!$C$6:$C$1000<=M24,Consolidado!$C$6:$C$1000,1)))} -> 0 | O24: {=MAX(IF(Consolidado!$A$6:$A$1000='TOTALES DIARIOS'!A24,IF(Consolidado!$D$6:$D$1000>=M24,Consolidado!$D$6:$D$1000,0)))} -> 0 | P24: {=MAX(IF(Consolidado!$A$6:$A$1000='TOTALES DIARIOS'!A24,IF(Consolidado!$D$6:$D$1000<=M24,Consolidado!$D$6:$D$1000,0)))} -> 0 | Q24: =IF(M24<>1,MAX(M24,N24),N24) -> 0 | R24: =IF(O24=0,P24,IF(P24=0,O24,MIN(P24,O24))) -> 0 | S24: =IF(D24>AB24,"SI","NO") -> NO | T24: 22 | U24: 30 | V24: 30
A25: =IFERROR(A24+1,"") -> 45313 | B25: =IF(G25=0,"",C25-"1:00") | C25: =Q25 -> 0 | D25: =R25 -> 0 | E25: =SUMIF(Consolidado!$A$6:$A$380,'TOTALES DIARIOS'!A25,Consolidado!$E$6:$E$380) -> 0 | F25: =SUMIF(Consolidado!$A$6:$A$380,'TOTALES DIARIOS'!A25,Consolidado!$F$6:$F$380) -> 0 | G25: =SUMIF(Consolidado!$A$6:$A$380,'TOTALES DIARIOS'!A25,Consolidado!$G$6:$G$380) -> 0 | H25: =IF(B25="",0,IF(B25<D25,D25-B25+"0:30","24:00"-B25+D25+"0:30"))*24 -> 0 | I25: =IF(G25<>0,1,0) -> 0 | J25: =IF(H25=0,0,IF((D25-"3:30")>(C25-"3:30"),1,2)) -> 0 | K25: =YEAR(A25) -> 2024 | L25: =MONTH(A25) -> 1 | M25: {=MIN(IF(Consolidado!$A$6:$A$1000='TOTALES DIARIOS'!A25,IF(Consolidado!$C$6:$C$1000>TIMEVALUE("07:00"),Consolidado!$C$6:$C$1000,1)))} -> 0 | N25: {=MIN(IF(Consolidado!$A$6:$A$1000='TOTALES DIARIOS'!A25,IF(Consolidado!$C$6:$C$1000<=M25,Consolidado!$C$6:$C$1000,1)))} -> 0 | O25: {=MAX(IF(Consolidado!$A$6:$A$1000='TOTALES DIARIOS'!A25,IF(Consolidado!$D$6:$D$1000>=M25,Consolidado!$D$6:$D$1000,0)))} -> 0 | P25: {=MAX(IF(Consolidado!$A$6:$A$1000='TOTALES DIARIOS'!A25,IF(Consolidado!$D$6:$D$1000<=M25,Consolidado!$D$6:$D$1000,0)))} -> 0 | Q25: =IF(M25<>1,MAX(M25,N25),N25) -> 0 | R25: =IF(O25=0,P25,IF(P25=0,O25,MIN(P25,O25))) -> 0 | S25: =IF(D25>AB25,"SI","NO") -> NO | T25: 23 | U25: 34 | V25: 34
A26: =IFERROR(A25+1,"") -> 45314 | B26: =IF(G26=0,"",C26-"1:00") | C26: =Q26 -> 0 | D26: =R26 -> 0 | E26: =SUMIF(Consolidado!$A$6:$A$380,'TOTALES DIARIOS'!A26,Consolidado!$E$6:$E$380) -> 0 | F26: =SUMIF(Consolidado!$A$6:$A$380,'TOTALES DIARIOS'!A26,Consolidado!$F$6:$F$380) -> 0 | G26: =SUMIF(Consolidado!$A$6:$A$380,'TOTALES DIARIOS'!A26,Consolidado!$G$6:$G$380) -> 0 | H26: =IF(B26="",0,IF(B26<D26,D26-B26+"0:30","24:00"-B26+D26+"0:30"))*24 -> 0 | I26: =IF(G26<>0,1,0) -> 0 | J26: =IF(H26=0,0,IF((D26-"3:30")>(C26-"3:30"),1,2)) -> 0 | K26: =YEAR(A26) -> 2024 | L26: =MONTH(A26) -> 1 | M26: {=MIN(IF(Consolidado!$A$6:$A$1000='TOTALES DIARIOS'!A26,IF(Consolidado!$C$6:$C$1000>TIMEVALUE("07:00"),Consolidado!$C$6:$C$1000,1)))} -> 0 | N26: {=MIN(IF(Consolidado!$A$6:$A$1000='TOTALES DIARIOS'!A26,IF(Consolidado!$C$6:$C$1000<=M26,Consolidado!$C$6:$C$1000,1)))} -> 0 | O26: {=MAX(IF(Consolidado!$A$6:$A$1000='TOTALES DIARIOS'!A26,IF(Consolidado!$D$6:$D$1000>=M26,Consolidado!$D$6:$D$1000,0)))} -> 0 | P26: {=MAX(IF(Consolidado!$A$6:$A$1000='TOTALES DIARIOS'!A26,IF(Consolidado!$D$6:$D$1000<=M26,Consolidado!$D$6:$D$1000,0)))} -> 0 | Q26: =IF(M26<>1,MAX(M26,N26),N26) -> 0 | R26: =IF(O26=0,P26,IF(P26=0,O26,MIN(P26,O26))) -> 0 | S26: =IF(D26>AB26,"SI","NO") -> NO | T26: 24 | U26: 36 | V26: 36
A27: =IFERROR(A26+1,"") -> 45315 | B27: =IF(G27=0,"",C27-"1:00") | C27: =Q27 -> 0 | D27: =R27 -> 0 | E27: =SUMIF(Consolidado!$A$6:$A$380,'TOTALES DIARIOS'!A27,Consolidado!$E$6:$E$380) -> 0 | F27: =SUMIF(Consolidado!$A$6:$A$380,'TOTALES DIARIOS'!A27,Consolidado!$F$6:$F$380) -> 0 | G27: =SUMIF(Consolidado!$A$6:$A$380,'TOTALES DIARIOS'!A27,Consolidado!$G$6:$G$380) -> 0 | H27: =IF(B27="",0,IF(B27<D27,D27-B27+"0:30","24:00"-B27+D27+"0:30"))*24 -> 0 | I27: =IF(G27<>0,1,0) -> 0 | J27: =IF(H27=0,0,IF((D27-"3:30")>(C27-"3:30"),1,2)) -> 0 | K27: =YEAR(A27) -> 2024 | L27: =MONTH(A27) -> 1 | M27: {=MIN(IF(Consolidado!$A$6:$A$1000='TOTALES DIARIOS'!A27,IF(Consolidado!$C$6:$C$1000>TIMEVALUE("07:00"),Consolidado!$C$6:$C$1000,1)))} -> 0 | N27: {=MIN(IF(Consolidado!$A$6:$A$1000='TOTALES DIARIOS'!A27,IF(Consolidado!$C$6:$C$1000<=M27,Consolidado!$C$6:$C$1000,1)))} -> 0 | O27: {=MAX(IF(Consolidado!$A$6:$A$1000='TOTALES DIARIOS'!A27,IF(Consolidado!$D$6:$D$1000>=M27,Consolidado!$D$6:$D$1000,0)))} -> 0 | P27: {=MAX(IF(Consolidado!$A$6:$A$1000='TOTALES DIARIOS'!A27,IF(Consolidado!$D$6:$D$1000<=M27,Consolidado!$D$6:$D$1000,0)))} -> 0 | Q27: =IF(M27<>1,MAX(M27,N27),N27) -> 0 | R27: =IF(O27=0,P27,IF(P27=0,O27,MIN(P27,O27))) -> 0 | S27: =IF(D27>AB27,"SI","NO") -> NO
A28: =IFERROR(A27+1,"") -> 45316 | B28: =IF(G28=0,"",C28-"1:00") | C28: =Q28 -> 0 | D28: =R28 -> 0 | E28: =SUMIF(Consolidado!$A$6:$A$380,'TOTALES DIARIOS'!A28,Consolidado!$E$6:$E$380) -> 0 | F28: =SUMIF(Consolidado!$A$6:$A$380,'TOTALES DIARIOS'!A28,Consolidado!$F$6:$F$380) -> 0 | G28: =SUMIF(Consolidado!$A$6:$A$380,'TOTALES DIARIOS'!A28,Consolidado!$G$6:$G$380) -> 0 | H28: =IF(B28="",0,IF(B28<D28,D28-B28+"0:30","24:00"-B28+D28+"0:30"))*24 -> 0 | I28: =IF(G28<>0,1,0) -> 0 | J28: =IF(H28=0,0,IF((D28-"3:30")>(C28-"3:30"),1,2)) -> 0 | K28: =YEAR(A28) -> 2024 | L28: =MONTH(A28) -> 1 | M28: {=MIN(IF(Consolidado!$A$6:$A$1000='TOTALES DIARIOS'!A28,IF(Consolidado!$C$6:$C$1000>TIMEVALUE("07:00"),Consolidado!$C$6:$C$1000,1)))} -> 0 | N28: {=MIN(IF(Consolidado!$A$6:$A$1000='TOTALES DIARIOS'!A28,IF(Consolidado!$C$6:$C$1000<=M28,Consolidado!$C$6:$C$1000,1)))} -> 0 | O28: {=MAX(IF(Consolidado!$A$6:$A$1000='TOTALES DIARIOS'!A28,IF(Consolidado!$D$6:$D$1000>=M28,Consolidado!$D$6:$D$1000,0)))} -> 0 | P28: {=MAX(IF(Consolidado!$A$6:$A$1000='TOTALES DIARIOS'!A28,IF(Consolidado!$D$6:$D$1000<=M28,Consolidado!$D$6:$D$1000,0)))} -> 0 | Q28: =IF(M28<>1,MAX(M28,N28),N28) -> 0 | R28: =IF(O28=0,P28,IF(P28=0,O28,MIN(P28,O28))) -> 0 | S28: =IF(D28>AB28,"SI","NO") -> NO
A29: =IFERROR(A28+1,"") -> 45317 | B29: =IF(G29=0,"",C29-"1:00") | C29: =Q29 -> 0 | D29: =R29 -> 0 | E29: =SUMIF(Consolidado!$A$6:$A$380,'TOTALES DIARIOS'!A29,Consolidado!$E$6:$E$380) -> 0 | F29: =SUMIF(Consolidado!$A$6:$A$380,'TOTALES DIARIOS'!A29,Consolidado!$F$6:$F$380) -> 0 | G29: =SUMIF(Consolidado!$A$6:$A$380,'TOTALES DIARIOS'!A29,Consolidado!$G$6:$G$380) -> 0 | H29: =IF(B29="",0,IF(B29<D29,D29-B29+"0:30","24:00"-B29+D29+"0:30"))*24 -> 0 | I29: =IF(G29<>0,1,0) -> 0 | J29: =IF(H29=0,0,IF((D29-"3:30")>(C29-"3:30"),1,2)) -> 0 | K29: =YEAR(A29) -> 2024 | L29: =MONTH(A29) -> 1 | M29: {=MIN(IF(Consolidado!$A$6:$A$1000='TOTALES DIARIOS'!A29,IF(Consolidado!$C$6:$C$1000>TIMEVALUE("07:00"),Consolidado!$C$6:$C$1000,1)))} -> 0 | N29: {=MIN(IF(Consolidado!$A$6:$A$1000='TOTALES DIARIOS'!A29,IF(Consolidado!$C$6:$C$1000<=M29,Consolidado!$C$6:$C$1000,1)))} -> 0 | O29: {=MAX(IF(Consolidado!$A$6:$A$1000='TOTALES DIARIOS'!A29,IF(Consolidado!$D$6:$D$1000>=M29,Consolidado!$D$6:$D$1000,0)))} -> 0 | P29: {=MAX(IF(Consolidado!$A$6:$A$1000='TOTALES DIARIOS'!A29,IF(Consolidado!$D$6:$D$1000<=M29,Consolidado!$D$6:$D$1000,0)))} -> 0 | Q29: =IF(M29<>1,MAX(M29,N29),N29) -> 0 | R29: =IF(O29=0,P29,IF(P29=0,O29,MIN(P29,O29))) -> 0 | S29: =IF(D29>AB29,"SI","NO") -> NO
A30: =IFERROR(A29+1,"") -> 45318 | B30: =IF(G30=0,"",C30-"1:00") | C30: =Q30 -> 0 | D30: =R30 -> 0 | E30: =SUMIF(Consolidado!$A$6:$A$380,'TOTALES DIARIOS'!A30,Consolidado!$E$6:$E$380) -> 0 | F30: =SUMIF(Consolidado!$A$6:$A$380,'TOTALES DIARIOS'!A30,Consolidado!$F$6:$F$380) -> 0 | G30: =SUMIF(Consolidado!$A$6:$A$380,'TOTALES DIARIOS'!A30,Consolidado!$G$6:$G$380) -> 0 | H30: =IF(B30="",0,IF(B30<D30,D30-B30+"0:30","24:00"-B30+D30+"0:30"))*24 -> 0 | I30: =IF(G30<>0,1,0) -> 0 | J30: =IF(H30=0,0,IF((D30-"3:30")>(C30-"3:30"),1,2)) -> 0 | K30: =YEAR(A30) -> 2024 | L30: =MONTH(A30) -> 1 | M30: {=MIN(IF(Consolidado!$A$6:$A$1000='TOTALES DIARIOS'!A30,IF(Consolidado!$C$6:$C$1000>TIMEVALUE("07:00"),Consolidado!$C$6:$C$1000,1)))} -> 0 | N30: {=MIN(IF(Consolidado!$A$6:$A$1000='TOTALES DIARIOS'!A30,IF(Consolidado!$C$6:$C$1000<=M30,Consolidado!$C$6:$C$1000,1)))} -> 0 | O30: {=MAX(IF(Consolidado!$A$6:$A$1000='TOTALES DIARIOS'!A30,IF(Consolidado!$D$6:$D$1000>=M30,Consolidado!$D$6:$D$1000,0)))} -> 0 | P30: {=MAX(IF(Consolidado!$A$6:$A$1000='TOTALES DIARIOS'!A30,IF(Consolidado!$D$6:$D$1000<=M30,Consolidado!$D$6:$D$1000,0)))} -> 0 | Q30: =IF(M30<>1,MAX(M30,N30),N30) -> 0 | R30: =IF(O30=0,P30,IF(P30=0,O30,MIN(P30,O30))) -> 0 | S30: =IF(D30>AB30,"SI","NO") -> NO
A31: =IFERROR(A30+1,"") -> 45319 | B31: =IF(G31=0,"",C31-"1:00") | C31: =Q31 -> 0 | D31: =R31 -> 0 | E31: =SUMIF(Consolidado!$A$6:$A$380,'TOTALES DIARIOS'!A31,Consolidado!$E$6:$E$380) -> 0 | F31: =SUMIF(Consolidado!$A$6:$A$380,'TOTALES DIARIOS'!A31,Consolidado!$F$6:$F$380) -> 0 | G31: =SUMIF(Consolidado!$A$6:$A$380,'TOTALES DIARIOS'!A31,Consolidado!$G$6:$G$380) -> 0 | H31: =IF(B31="",0,IF(B31<D31,D31-B31+"0:30","24:00"-B31+D31+"0:30"))*24 -> 0 | I31: =IF(G31<>0,1,0) -> 0 | J31: =IF(H31=0,0,IF((D31-"3:30")>(C31-"3:30"),1,2)) -> 0 | K31: =YEAR(A31) -> 2024 | L31: =MONTH(A31) -> 1 | M31: {=MIN(IF(Consolidado!$A$6:$A$1000='TOTALES DIARIOS'!A31,IF(Consolidado!$C$6:$C$1000>TIMEVALUE("07:00"),Consolidado!$C$6:$C$1000,1)))} -> 0 | N31: {=MIN(IF(Consolidado!$A$6:$A$1000='TOTALES DIARIOS'!A31,IF(Consolidado!$C$6:$C$1000<=M31,Consolidado!$C$6:$C$1000,1)))} -> 0 | O31: {=MAX(IF(Consolidado!$A$6:$A$1000='TOTALES DIARIOS'!A31,IF(Consolidado!$D$6:$D$1000>=M31,Consolidado!$D$6:$D$1000,0)))} -> 0 | P31: {=MAX(IF(Consolidado!$A$6:$A$1000='TOTALES DIARIOS'!A31,IF(Consolidado!$D$6:$D$1000<=M31,Consolidado!$D$6:$D$1000,0)))} -> 0 | Q31: =IF(M31<>1,MAX(M31,N31),N31) -> 0 | R31: =IF(O31=0,P31,IF(P31=0,O31,MIN(P31,O31))) -> 0 | S31: =IF(D31>AB31,"SI","NO") -> NO
A32: =IFERROR(A31+1,"") -> 45320 | B32: =IF(G32=0,"",C32-"1:00") | C32: =Q32 -> 0 | D32: =R32 -> 0 | E32: =SUMIF(Consolidado!$A$6:$A$380,'TOTALES DIARIOS'!A32,Consolidado!$E$6:$E$380) -> 0 | F32: =SUMIF(Consolidado!$A$6:$A$380,'TOTALES DIARIOS'!A32,Consolidado!$F$6:$F$380) -> 0 | G32: =SUMIF(Consolidado!$A$6:$A$380,'TOTALES DIARIOS'!A32,Consolidado!$G$6:$G$380) -> 0 | H32: =IF(B32="",0,IF(B32<D32,D32-B32+"0:30","24:00"-B32+D32+"0:30"))*24 -> 0 | I32: =IF(G32<>0,1,0) -> 0 | J32: =IF(H32=0,0,IF((D32-"3:30")>(C32-"3:30"),1,2)) -> 0 | K32: =YEAR(A32) -> 2024 | L32: =MONTH(A32) -> 1 | M32: {=MIN(IF(Consolidado!$A$6:$A$1000='TOTALES DIARIOS'!A32,IF(Consolidado!$C$6:$C$1000>TIMEVALUE("07:00"),Consolidado!$C$6:$C$1000,1)))} -> 0 | N32: {=MIN(IF(Consolidado!$A$6:$A$1000='TOTALES DIARIOS'!A32,IF(Consolidado!$C$6:$C$1000<=M32,Consolidado!$C$6:$C$1000,1)))} -> 0 | O32: {=MAX(IF(Consolidado!$A$6:$A$1000='TOTALES DIARIOS'!A32,IF(Consolidado!$D$6:$D$1000>=M32,Consolidado!$D$6:$D$1000,0)))} -> 0 | P32: {=MAX(IF(Consolidado!$A$6:$A$1000='TOTALES DIARIOS'!A32,IF(Consolidado!$D$6:$D$1000<=M32,Consolidado!$D$6:$D$1000,0)))} -> 0 | Q32: =IF(M32<>1,MAX(M32,N32),N32) -> 0 | R32: =IF(O32=0,P32,IF(P32=0,O32,MIN(P32,O32))) -> 0 | S32: =IF(D32>AB32,"SI","NO") -> NO
A33: =IFERROR(A32+1,"") -> 45321 | B33: =IF(G33=0,"",C33-"1:00") | C33: =Q33 -> 0 | D33: =R33 -> 0 | E33: =SUMIF(Consolidado!$A$6:$A$380,'TOTALES DIARIOS'!A33,Consolidado!$E$6:$E$380) -> 0 | F33: =SUMIF(Consolidado!$A$6:$A$380,'TOTALES DIARIOS'!A33,Consolidado!$F$6:$F$380) -> 0 | G33: =SUMIF(Consolidado!$A$6:$A$380,'TOTALES DIARIOS'!A33,Consolidado!$G$6:$G$380) -> 0 | H33: =IF(B33="",0,IF(B33<D33,D33-B33+"0:30","24:00"-B33+D33+"0:30"))*24 -> 0 | I33: =IF(G33<>0,1,0) -> 0 | J33: =IF(H33=0,0,IF((D33-"3:30")>(C33-"3:30"),1,2)) -> 0 | K33: =YEAR(A33) -> 2024 | L33: =MONTH(A33) -> 1 | M33: {=MIN(IF(Consolidado!$A$6:$A$1000='TOTALES DIARIOS'!A33,IF(Consolidado!$C$6:$C$1000>TIMEVALUE("07:00"),Consolidado!$C$6:$C$1000,1)))} -> 0 | N33: {=MIN(IF(Consolidado!$A$6:$A$1000='TOTALES DIARIOS'!A33,IF(Consolidado!$C$6:$C$1000<=M33,Consolidado!$C$6:$C$1000,1)))} -> 0 | O33: {=MAX(IF(Consolidado!$A$6:$A$1000='TOTALES DIARIOS'!A33,IF(Consolidado!$D$6:$D$1000>=M33,Consolidado!$D$6:$D$1000,0)))} -> 0 | P33: {=MAX(IF(Consolidado!$A$6:$A$1000='TOTALES DIARIOS'!A33,IF(Consolidado!$D$6:$D$1000<=M33,Consolidado!$D$6:$D$1000,0)))} -> 0 | Q33: =IF(M33<>1,MAX(M33,N33),N33) -> 0 | R33: =IF(O33=0,P33,IF(P33=0,O33,MIN(P33,O33))) -> 0 | S33: =IF(D33>AB33,"SI","NO") -> NO
A34: =IFERROR(A33+1,"") -> 45322 | B34: =IF(G34=0,"",C34-"1:00") | C34: =Q34 -> 0 | D34: =R34 -> 0 | E34: =SUMIF(Consolidado!$A$6:$A$380,'TOTALES DIARIOS'!A34,Consolidado!$E$6:$E$380) -> 0 | F34: =SUMIF(Consolidado!$A$6:$A$380,'TOTALES DIARIOS'!A34,Consolidado!$F$6:$F$380) -> 0 | G34: =SUMIF(Consolidado!$A$6:$A$380,'TOTALES DIARIOS'!A34,Consolidado!$G$6:$G$380) -> 0 | H34: =IF(B34="",0,IF(B34<D34,D34-B34+"0:30","24:00"-B34+D34+"0:30"))*24 -> 0 | I34: =IF(G34<>0,1,0) -> 0 | J34: =IF(H34=0,0,IF((D34-"3:30")>(C34-"3:30"),1,2)) -> 0 | K34: =YEAR(A34) -> 2024 | L34: =MONTH(A34) -> 1 | M34: {=MIN(IF(Consolidado!$A$6:$A$1000='TOTALES DIARIOS'!A34,IF(Consolidado!$C$6:$C$1000>TIMEVALUE("07:00"),Consolidado!$C$6:$C$1000,1)))} -> 0 | N34: {=MIN(IF(Consolidado!$A$6:$A$1000='TOTALES DIARIOS'!A34,IF(Consolidado!$C$6:$C$1000<=M34,Consolidado!$C$6:$C$1000,1)))} -> 0 | O34: {=MAX(IF(Consolidado!$A$6:$A$1000='TOTALES DIARIOS'!A34,IF(Consolidado!$D$6:$D$1000>=M34,Consolidado!$D$6:$D$1000,0)))} -> 0 | P34: {=MAX(IF(Consolidado!$A$6:$A$1000='TOTALES DIARIOS'!A34,IF(Consolidado!$D$6:$D$1000<=M34,Consolidado!$D$6:$D$1000,0)))} -> 0 | Q34: =IF(M34<>1,MAX(M34,N34),N34) -> 0 | R34: =IF(O34=0,P34,IF(P34=0,O34,MIN(P34,O34))) -> 0 | S34: =IF(D34>AB34,"SI","NO") -> NO
